Workbook

Sheet 功能点清单
A1: 序号 | B1: 系统 | C1: 类型 | D1: 功能点 | E1: 开发负责人 | F1: 备注
A2: 1 | B2: DOP | C2: 底表 | D2: 工单齐套_工单详情 | E2: 万文豪
A3: 2 | B3: DOP | C3: 底表 | D3: 工单齐套明细表 | E3: 万文豪
A4: 3 | B4: DOP | C4: 底表 | D4: 工单齐套_物料详情 | E4: 万文豪
A5: 4 | B5: DOP | C5: 底表 | D5: 工单齐套优先级配置表 | E5: 万文豪
A6: 5 | B6: DOP | C6: 底表 | D6: 计算子库存净值名称 下级配置表 | E6: 万文豪
A7: 6 | B7: DOP | C7: 底表 | D7: 配置表_齐套规则计算配置表 | E7: 万文豪
A8: 7 | B8: DOP | C8: 底表 | D8: 配置表_组件责任方 | E8: 万文豪
A9: 8 | B9: DOP | C9: 底表 | D9: 齐套明细运行历史记录表 | E9: 万文豪
A10: 9 | B10: OMS | C10: 改造 | D10: OMS，工单变更时"起始MRP日期"变为可变更字段 | E10: 陆勇君
A11: 10 | B11: OMS | C11: 改造 | D11: OMS订单页面，"要求完成日期"改必填 | E11: 陆勇君
A12: 11 | B12: DOP | C12: 接口 | D12: DOP->EBS PO信息查询接口 | E12: 万文豪,严居兆
A13: 12 | B13: DOP | C13: 接口 | D13: DOP->EBS PR信息查询接口 | E13: 万文豪,严居兆
... A41: 40 | B41: DOP | C41: 前端页面 | D41: WO工单信息表 | E41: 万文豪

Sheet 字段列表
A1: 中文名称 | B1: 字段名(开发自定义) | C1: 数据类型 | D1: 备注 | E1: 基础查询 | F1: 高级查询 | G1: 查询方式
A2: 报废数量 | B2: scrapQty | C2: VARCHAR | E2: - | F2: Y | G2: NUM
A3: 必需 | B3: isRequired | C3: VARCHAR | D3: 数量 | E3: - | F3: Y | G3: NUM
A4: 仓位名称 | B4: locationCode | C4: VARCHAR | E4: Y | F4: Y | G4: SEL-2
A5: 仓位说明 | B5: locationName | C5: VARCHAR | E5: - | F5: - | G5: -
A6: 操作 | B6: operations | C6: _ | D6: 前端渲染用，无实际字段 | E6: - | F6: - | G6: -
A7: 产出率 | B7: yieldRate | C7: VARCHAR | D7: 如0.98表示98% | E7: - | F7: Y | G7: NUM
A8: 组织 | B8: orgName | C8: VARCHAR | D8: 组织名称，另有组织ID | E8: Y | F8: Y | G8: SEL-1
A9: 组织ID | B9: orgId | C9: VARCHAR | D9: 可用Long，视系统而定 | E9: - | F9: Y | G9: SEL-2
A10: 产品线 | B10: productLine | C10: VARCHAR | E10: - | F10: Y | G10: SEL-2
A11: 订单编号 | B11: orderNo | C11: VARCHAR | E11: Y | F11: Y | G11: TXT-1
A12: 创建日期 | B12: createDate | C12: Date | E12: - | F12: Y | G12: DATA
A13: 单位用量 | B13: unitUsage | C13: VARCHAR | E13: - | F13: Y | G13: NUM
A14: 工单号 | B14: workOrderNo | C14: VARCHAR | E14: Y | F14: Y | G14: TXT-1
A15: 料号 | B15: materialCode | C15: VARCHAR | D15: 物料编码 | E15: Y | F15: Y | G15: TXT-1
A16: 配置编码 | B16: configCode | C16: VARCHAR | D16: 所有涉及到该字段的屏幕，在查询和运行时，必填 | E16: Y | F16: Y | G16: TXT-1
A17: 订单创建日期 | B17: orderCreateDate | C17: Date | E17: - | F17: Y | G17: DATA
A18: 订单类型 | B18: orderType | C18: VARCHAR | E18: Y | F18: Y | G18: SEL-2
A19: 发料仓 | B19: issueWarehouse | C19: VARCHAR | D19: 仓库编码和名称 | E19: - | F19: Y | G19: SEL-2
A20: 分类码 | B20: categoryCode | C20: VARCHAR | E20: - | F20: Y | G20: SEL-2
A21: 工单分类 | B21: workOrderCategory | C21: VARCHAR | E21: - | F21: Y | G21: SEL-2
A22: 组件物料 | B22: componentMaterialCode | C22: VARCHAR | D22: 组件物料编码 | E22: Y | F22: Y | G22: TXT-1
A23: 工单缺料数量 | B23: woShortageQty | C23: VARCHAR | E23: - | F23: Y | G23: NUM
A24: 工单优先级 | B24: workOrderPriority | C24: INT | D24: HIGH/MEDIUM/LOW | E24: Y | F24: Y | G24: NUM
A25: 工单状态 | B25: workOrderStatus | C25: VARCHAR | D25: 进行中、完工、完工不计费 | E25: - | F25: Y | G25: SEL-2
A26: 供给明细 | B26: supplyDetails | C26: _ | D26: 前端渲染用，无实际字段 | E26: - | F26: - | G26: -
A27: 供应商编码 | B27: supplierCode | C27: VARCHAR | E27: - | F27: Y | G27: SEL-2
A28: 供应商简称 | B28: supplierDesc | C28: VARCHAR | E28: - | F28: - | G28: -
A29: EBS供给仓位配置 | B29: calcSubInvNetValueName | C29: VARCHAR | E29: - | F29: Y | G29: SEL-2
A30: EBS供给仓位配置说明 | B30: calcSubInvNetValueDesc | C30: VARCHAR | E30: - | F30: - | G30: -
A31: 可用库存缺料数 | B31: availableStockShortageQty | C31: VARCHAR | E31: - | F31: Y | G31: NUM
A32: 可用量 | B32: availableQty | C32: VARCHAR | E32: - | F32: Y | G32: NUM
A33: 理论可用库存 | B33: theoreticalAvailableStock | C33: VARCHAR | E33: - | F33: Y | G33: NUM
A34: 理论可用库存(含PO&工单) | B34: theoreticalAvailableStockInclPoWo | C34: VARCHAR | E34: - | F34: Y | G34: NUM
A35: 创建人 | B35: createdBy | C35: VARCHAR | E35: - | F35: Y | G35: TXT-2
A36: 零部件类别 | B36: componentCategory | C36: VARCHAR | E36: - | F36: Y | G36: SEL-2
A37: 订单创建人 | B37: orderCreator | C37: VARCHAR | E37: - | F37: Y | G37: TXT-2
A38: 配置库存数量 | B38: configInventoryQty | C38: VARCHAR | E38: - | F38: Y | G38: NUM
A39: 编辑人 | B39: updatedBy | C39: VARCHAR | E39: - | F39: Y | G39: TXT-2
A40: 齐套进度 | B40: kitProgress | C40: VARCHAR | D40: 比例0~1或百分数字符串 | E40: - | F40: - | G40: NUM
...

Sheet 屏幕编码清单
A1: 序号 | B1: 屏幕编号 | C1: 类型 | D1: 屏幕名称 | E1: 数据来源 | F1: 屏幕功能 | G1: 字段功能 | H1: 备注
A2: =ROW()-1 -> 1 | B2: C1 | C2: 表格 | D2: 齐套规则计算配置表 | E2: DOP存表 | F2: 查询、导出、保存、删除、行删除、行编辑、新增行、勾选框、重置 | G2: 基础查询、字段自定义升降序、自定义字段布局保存 | H2: 点击可编辑字段，进行相关数据的维护配置
A3: =ROW()-1 -> 2 | B3: C1_1 | C3: 弹窗 | D3: 齐套规则计算配置表-组织配置屏幕 | E3: DOP存表 | F3: 查询、确认、取消、勾选框，全选/反选 | G3: 基础查询 | H3: 在C1屏幕，进行"组织"配置时的"抽屉"弹窗
A4: =ROW()-1 -> 3 | B4: C1_2 | C4: 弹窗 | D4: 齐套规则计算配置表-分类码配置屏幕 | E4: DOP存表 | F4: 查询、确认、取消、勾选框，全选/反选 | G4: 基础查询 | H4: 在C1屏幕，进行"分类码"配置时的"抽屉"弹窗
A5: =ROW()-1 -> 4 | B5: C1_3 | C5: 弹窗 | D5: 齐套规则计算配置表-供给仓位配置 | E5: DOP存表 | F5: 查询、确认、取消、勾选框，全选/反选 | G5: 基础查询 | H5: 在C1屏幕，进行"供给仓位"配置时的"抽屉"弹窗
A6: =ROW()-1 -> 5 | B6: C1_3_1 | C6: 弹窗 | D6: 齐套规则计算配置表-供给仓位配置-仓位选择 | E6: DOP存表 | F6: 查询、确认、取消、勾选框，全选/反选 | G6: 基础查询 | H6: 在C1_3屏幕，进行"EBS供给仓位配置"时，弹窗
A7: =ROW()-1 -> 6 | B7: C1_4 | C7: 弹窗 | D7: 齐套规则计算配置表-供应商配置屏幕 | E7: DOP存表 | F7: 查询、确认、取消、勾选框，全选/反选 | G7: 基础查询 | H7: 在C1屏幕，进行"供应商"配置时的"抽屉"弹窗
A8: =ROW()-1 -> 7 | B8: C1_5 | C8: 弹窗 | D8: 齐套规则计算配置表-工单状态配置屏幕 | E8: DOP存表 | F8: 查询、确认、取消、勾选框，全选/反选 | G8: 基础查询 | H8: 在C1屏幕，进行"工单状态"配置时的"抽屉"弹窗
A9: =ROW()-1 -> 8 | B9: C2 | C9: 表格 | D9: 工单齐套优先级维护表 | E9: DOP存表 | F9: 查询、导出、保存、导入、行项编辑、重置 | G9: 基础查询、高级查询、字段自定义升降序、自定义字段布局保存
A10: =ROW()-1 -> 9 | B10: C3 | C10: 表格 | D10: 组件责任方配置 | E10: EBS | F10: 查询、导出、重置 | G10: 基础查询、高级查询、字段自定义升降序、自定义字段布局保存 | H10: -
A11: 19 | B11: H1 | C11: 表格 | D11: 齐套明细运行历史记录表 | E11: DOP存表 | F11: 查询、重置 | G11: 基础查询、字段自定义升降序 | H11: M1/M2/M3屏幕，点击"配置编码"跳转到当前屏幕 在当前屏幕点击'配置编码"跳转到M1屏幕
A12: =ROW()-1 -> 11 | B12: M1 | C12: 表格 | D12: 工单齐套明细 | E12: DOP存表 | F12: 查询、导出、齐套运行、重置 | G12: 基础查询、高级查询、字段自定义升降序、自定义字段布局保存 | H12: -
A13: =ROW()-1 -> 12 | B13: M1_1 | C13: 弹窗 | D13: WO工单信息表 | E13: EBS | F13: 查询、重置 | H13: 在"M1 工单齐套明细 "&"M3 工单齐套-物料详细"&"M2_1工单齐套-工单详细-工单组件信息"屏幕，点击"供给明细-WO"抽屉弹窗
A14: =ROW()-1 -> 13 | B14: M2 | C14: 表格 | D14: 工单齐套-工单详情 | E14: SRM | F14: 查询、导出、重置 | G14: 基础查询、高级查询、字段自定义升降序、自定义字段布局保存 | H14: 在M1屏幕，可点击"操作-工单详情"，跳转到该屏幕
A15: =ROW()-1 -> 14 | B15: M2_1 | C15: 弹窗 | D15: 工单齐套-工单详细-工单组件信息 | E15: EBS | F15: 查询、重置 | H15: 在M2屏幕，点击""的"抽屉"弹窗
A16: =ROW()-1 -> 15 | B16: M3 | C16: 表格 | D16: 工单齐套-物料详细 | E16: DOP存表 | F16: 查询、导出、重置 | G16: 基础查询、高级查询、字段自定义升降序、自定义字段布局保存 | H16: 在M1屏幕，可点击"操作-物料详情"，跳转到该屏幕
A17: =ROW()-1 -> 16 | B17: M3_1 | C17: 弹窗 | D17: 工单齐套-物料详情-物料关联工单信息 | E17: DOP存表 | F17: 查询、重置 | H17: 在M3_1屏幕，点击"关联工单"的，抽屉弹窗
A18: =ROW()-1 -> 17 | B18: T1 | C18: 表格 | D18: SRM PO交期报表 | E18: DOP存表 | F18: 查询、导出、重置 | G18: 基础查询、高级查询、字段自定义升降序、自定义字段布局保存 | H18: 在"M1 工单齐套明细 "&"M3 工单齐套-物料详细"&"M2_1工单齐套-工单详细-工单组件信息"屏幕，点击"供给明细-PO" 跳转表格
A19: =ROW()-1 -> 18 | B19: T2 | C19: 表格 | D19: PR信息表 | E19: DOP存表 | F19: 查询、导出、重置 | G19: 基础查询、高级查询、字段自定义升降序、自定义字段布局保存 | H19: 在"M1 工单齐套明细 "&"M3 工单齐套-物料详细"&"M2_1工单齐套-工单详细-工单组件信息"屏幕，点击"供给明细-PR" 跳转表格
A20: =ROW()-1 -> 19 | B20: T3 | C20: 表格 | D20: 替代料明细 | E20: DOP存表 | F20: 查询、导出、重置 | G20: 基础查询、高级查询 | H20: 在"M1 工单齐套明细 "，点击"替代料"抽屉弹窗

Sheet 查询规则
A1: 搜索编号 | B1: 搜索方式 | C1: 控件类型 | D1: 通配符查询 | E1: 多值分隔方式 | F1: 搜索历史记录 | G1: 是否支持高级查询 | H1: 高级查询可用运算符 | I1: 备注
A2: TXT_1 | B2: TXT_MULTI | C2: 输入框（多条件输入） | D2: - | E2: 英文逗号 | F2: 是（按整串存储） | G2: 是 | H2: 等于、不等于、包含、不包含（用于 IN / NOT IN）
A3: TXT_2 | B3: TXT_SINGLE | C3: 输入框 | D3: * | E3: - | F3: 是 | G3: 是 | H3: 等于、不等于、包含、不包含、开头是、结尾是、为空、不为空
A4: SEL_1 | B4: SEL_SINGLE | C4: 下拉单选 | D4: - | E4: - | F4: 否 | G4: 是 | H4: 等于、不等于、为空、不为空
A5: SEL_2 | B5: SEL_MULTI | C5: 下拉多选（含全选，反选） | D5: - | E5: 多选值以 数组 传递 | F5: 否 | G5: 是 | H5: 等于、不等于、为空、不为空
A6: NUM | B6: NUM-RANGE | C6: 最小值、最大值输入框 | D6: - | E6: - | F6: 否 | G6: 是 | H6: 等于、不等于、大于、小于、大于等于、小于等于、区间、为空、不为空 | I6: 运算符选择区间时，弹出一个输入最小值的输入框
A7: DATA | B7: DATE-SINGLE | C7: 日期选择器 | D7: - | E7: - | F7: 否 | G7: 是 | H7: 等于、不等于、早于、大于、小于、大于等于、小于等于、不为空 | I7: 运算符选择区间时，弹出一个输入最小值的输入框
A8: BOOL | B8: BOOL | C8: 下拉（全部/是/否） | D8: - | E8: - | F8: 否 | G8: 是 | H8: 等于、不等于

Sheet 表关系图

Sheet 屏幕关系

Sheet C1 齐套规则计算配置表
A1: 序号 | B1: 字段描述 | C1: 字段名 | D1: 字段逻辑 | E1: 字符类型 | F1: 基础查询 | G1: 高级查询 | H1: 查询方式 | I1: 是否编辑 | J1: 备注
A2: =ROW()-1 -> 1 | B2: 配置编码 | C2: =VLOOKUP(B2,字段列表!A:D,2,0) -> configCode | D2: 自动给号，YY+MM+00001(五位流水)，按照如下配置项的数据，通过组成配置信息，过滤工单数据，进行齐套运算 | E2: =VLOOKUP(B2,字段列表!A:D,3,0) -> VARCHAR | F2: =VLOOKUP($C2,字段列表!$B:$F,4,0) -> Y | G2: =VLOOKUP($C2,字段列表!$B:$F,5,0) -> Y | H2: =VLOOKUP(C2,字段列表!B:G,6,0) -> TXT-1 | I2: -
A3: =ROW()-1 -> 2 | B3: 配置描述 | C3: =VLOOKUP(B3,字段列表!A:D,2,0) -> configDesc | D3: 自定义输入 | E3: =VLOOKUP(B3,字段列表!A:D,3,0) -> VARCHAR | F3: =VLOOKUP(C3,字段列表!B:F,4,0) -> - | G3: =VLOOKUP($C3,字段列表!$B:$F,5,0) -> Y | H3: =VLOOKUP(C3,字段列表!B:G,6,0) -> TXT-2 | I3: Y
A4: =ROW()-1 -> 3 | B4: 组织 | C4: =VLOOKUP(B4,字段列表!A:D,2,0) -> orgName | D4: 该字段需要优先配置并保存，未配置该字段情况下，不允许配置其它配置参数 按屏幕“C1_1”，勾选的组织显示数据，若多组织，按照英文逗号分隔 | E4: =VLOOKUP(B4,字段列表!A:D,3,0) -> VARCHAR | F4: =VLOOKUP(C4,字段列表!B:F,4,0) -> Y | G4: =VLOOKUP($C4,字段列表!$B:$F,5,0) -> Y | H4: =VLOOKUP(C4,字段列表!B:G,6,0) -> SEL-1 | I4: Y
A5: =ROW()-1 -> 4 | B5: 分类码 | C5: =VLOOKUP(B5,字段列表!A:D,2,0) -> categoryCode | D5: 配置值，按屏幕"C1_2"，勾选的"分类码"呈现 创建时，按照配置"组织"，到EBS取相应"组织"的"分类码" 编辑时，按照已保存的数据进行编辑新增 | E5: =VLOOKUP(B5,字段列表!A:D,3,0) -> VARCHAR | F5: =VLOOKUP(C5,字段列表!B:F,4,0) -> - | G5: =VLOOKUP($C5,字段列表!$B:$F,5,0) -> Y | H5: =VLOOKUP(C5,字段列表!B:G,6,0) -> SEL-2 | I5: Y
A6: =ROW()-1 -> 5 | B6: EBS供给仓位配置 | C6: =VLOOKUP(B6,字段列表!A:D,2,0) -> calcSubInvNetValueName | D6: 配置值，按屏幕"C1_3"，选择的屏幕呈现字段，该字段可点击"配置" 创建时，根据"组织"，到EBS取表"MRP_SCHEDULE_DESIGNATORS"，字段"SCHEDULE_DESIGNATOR"相应"组织"所有数据。 编辑时，按照已保存的数据进行编辑新增 | E6: =VLOOKUP(B6,字段列表!A:D,3,0) -> VARCHAR | F6: =VLOOKUP(C6,字段列表!B:F,4,0) -> - | G6: =VLOOKUP($C6,字段列表!$B:$F,5,0) -> Y | H6: =VLOOKUP(C6,字段列表!B:G,6,0) -> SEL-2 | I6: Y
A7: =ROW()-1 -> 6 | B7: EBS供给仓位配置说明 | C7: =VLOOKUP(B7,字段列表!A:D,2,0) -> calcSubInvNetValueDesc | D7: 配置值，按屏幕"C1_3"，选择的屏幕呈现字段 取EBS表"MRP_SCHEDULE_DESIGNATORS"，字段"DESCRIPTION_MIR" | E7: =VLOOKUP(B7,字段列表!A:D,3,0) -> VARCHAR | F7: =VLOOKUP(C7,字段列表!B:F,4,0) -> - | G7: =VLOOKUP($C7,字段列表!$B:$F,5,0) -> - | H7: =VLOOKUP(C7,字段列表!B:G,6,0) -> - | I7: -
A8: =ROW()-1 -> 7 | B8: 供应商编码 | C8: =VLOOKUP(B8,字段列表!A:D,2,0) -> supplierCode | D8: 取屏幕"C1_4"数据，可点击"配置" 当创建时，按照"组织"到，EBS取表"AP_SUPPLIERS"，字段"VENDOR_TYPE_LOOKUP_CODE"=委外供应商的，字段"SEGMENT1"。 编辑时，按照已保存的数据进行编辑新增 | E8: =VLOOKUP(B8,字段列表!A:D,3,0) -> VARCHAR | F8: =VLOOKUP(C8,字段列表!B:F,4,0) -> - | G8: =VLOOKUP($C8,字段列表!$B:$F,5,0) -> Y | H8: =VLOOKUP(C8,字段列表!B:G,6,0) -> SEL-2 | I8: Y
A9: =ROW()-1 -> 8 | B9: 供应商简称 | C9: =VLOOKUP(B9,字段列表!A:D,2,0) -> supplierDesc | D9: 取屏幕"C1_4"数据 根据"供应商编码SEGMENT1"字段到表"AP_SUPPLIERS"取"VENDOR_NAME"， | E9: =VLOOKUP(B9,字段列表!A:D,3,0) -> VARCHAR | F9: =VLOOKUP(C9,字段列表!B:F,4,0) -> - | G9: =VLOOKUP($C9,字段列表!$B:$F,5,0) -> - | H9: =VLOOKUP(C9,字段列表!B:G,6,0) -> - | I9: -
A10: =ROW()-1 -> 9 | B10: 工单状态 | C10: =VLOOKUP(B10,字段列表!A:D,2,0) -> workOrderStatus | D10: 取屏幕"C1_5"屏幕配置数据 | E10: =VLOOKUP(B10,字段列表!A:D,3,0) -> VARCHAR | F10: =VLOOKUP(C10,字段列表!B:F,4,0) -> - | G10: =VLOOKUP($C10,字段列表!$B:$F,5,0) -> Y | H10: =VLOOKUP(C10,字段列表!B:G,6,0) -> SEL-2 | I10: Y
A11: =ROW()-1 -> 10 | B11: 创建人 | C11: =VLOOKUP(B11,字段列表!A:D,2,0) -> createdBy | D11: 根据登录账户user，创建人自动赋值 | E11: =VLOOKUP(B11,字段列表!A:D,3,0) -> VARCHAR | F11: =VLOOKUP(C11,字段列表!B:F,4,0) -> - | G11: =VLOOKUP($C11,字段列表!$B:$F,5,0) -> Y | H11: =VLOOKUP(C11,字段列表!B:G,6,0) -> TXT-2 | I11: -
A12: =ROW()-1 -> 11 | B12: 创建日期 | C12: =VLOOKUP(B12,字段列表!A:D,2,0) -> createDate | D12: 根据创建日期自动赋值 | E12: =VLOOKUP(B12,字段列表!A:D,3,0) -> Date | F12: =VLOOKUP(C12,字段列表!B:F,4,0) -> - | G12: =VLOOKUP($C12,字段列表!$B:$F,5,0) -> Y | H12: =VLOOKUP(C12,字段列表!B:G,6,0) -> DATA | I12: -
A13: =ROW()-1 -> 12 | B13: 编辑人 | C13: =VLOOKUP(B13,字段列表!A:D,2,0) -> updatedBy | D13: 根据登录账户user，编辑人自动赋值 | E13: =VLOOKUP(B13,字段列表!A:D,3,0) -> VARCHAR | F13: =VLOOKUP(C13,字段列表!B:F,4,0) -> - | G13: =VLOOKUP($C13,字段列表!$B:$F,5,0) -> Y | H13: =VLOOKUP(C13,字段列表!B:G,6,0) -> TXT-2 | I13: -
A14: =ROW()-1 -> 13 | B14: 编辑日期 | C14: =VLOOKUP(B14,字段列表!A:D,2,0) -> updateDate | D14: 根据编辑时间自动赋值 | E14: =VLOOKUP(B14,字段列表!A:D,3,0) -> Date | F14: =VLOOKUP(C14,字段列表!B:F,4,0) -> - | G14: =VLOOKUP($C14,字段列表!$B:$F,5,0) -> Y | H14: =VLOOKUP(C14,字段列表!B:G,6,0) -> DATA | I14: -
A15: =ROW()-1 -> 14 | B15: 是否有效 | C15: =VLOOKUP(B15,字段列表!A:D,2,0) -> isActive | D15: 勾选框，选择该配置条件生效，并可以运行该配置条件 | E15: =VLOOKUP(B15,字段列表!A:D,3,0) -> Boolean | F15: =VLOOKUP(C15,字段列表!B:F,4,0) -> Y | G15: =VLOOKUP($C15,字段列表!$B:$F,5,0) -> Y | H15: =VLOOKUP(C15,字段列表!B:G,6,0) -> BOOL | I15: - | J15: 是/否/NULL

Sheet C1_1 齐套规则计算配置表-组织配置屏幕
A1: 字段描述 | B1: 字段名 | C1: 字段逻辑 | D1: 字符类型 | E1: 基础查询 | F1: 高级查询 | G1: 查询方式 | H1: 是否可编辑 | I1: 备注
A2: 序号 | B2: =VLOOKUP($A2,字段列表!$A:$G,2,0) -> seqNo | C2: 自动改给号 | D2: =VLOOKUP($A2,字段列表!$A:$G,3,0) -> VARCHAR | E2: =VLOOKUP($A2,字段列表!$A:$G,5,0) -> - | F2: =VLOOKUP($A2,字段列表!$A:$G,6,0) -> - | G2: =VLOOKUP($A2,字段列表!$A:$G,7,0) -> - | H2: -
A3: 是否启用 | B3: =VLOOKUP($A3,字段列表!$A:$G,2,0) -> isEnabled | C3: 默认不勾选，当勾选时，即考虑所选组织的工单取值范围，支持多条件勾选，表头列字段，支持一键全选，取消全选 | D3: =VLOOKUP($A3,字段列表!$A:$G,3,0) -> Boolean | E3: =VLOOKUP($A3,字段列表!$A:$G,5,0) -> Y | F3: =VLOOKUP($A3,字段列表!$A:$G,6,0) -> Y | G3: =VLOOKUP($A3,字段列表!$A:$G,7,0) -> BOOL | H3: Y
A4: 组织ID | B4: =VLOOKUP($A4,字段列表!$A:$G,2,0) -> orgId | C4: 初始化配置时，默认读取EBS全"组织" 配置值，支持勾选多组织，取EBS表"HR_ORGANIZATION_UNITS_V'，值'ORGANIZATION_CODE'，在每次查询时，动态取EBS组织清单 | D4: =VLOOKUP($A4,字段列表!$A:$G,3,0) -> VARCHAR | E4: =VLOOKUP($A4,字段列表!$A:$G,5,0) -> - | F4: =VLOOKUP($A4,字段列表!$A:$G,6,0) -> Y | G4: =VLOOKUP($A4,字段列表!$A:$G,7,0) -> SEL-2 | H4: Y
A5: 组织 | B5: =VLOOKUP($A5,字段列表!$A:$G,2,0) -> orgName | C5: 通过组织ID 获取 | D5: =VLOOKUP($A5,字段列表!$A:$G,3,0) -> VARCHAR | E5: =VLOOKUP($A5,字段列表!$A:$G,5,0) -> Y | F5: =VLOOKUP($A5,字段列表!$A:$G,6,0) -> Y | G5: =VLOOKUP($A5,字段列表!$A:$G,7,0) -> SEL-1 | H5: -

Sheet C1_2 齐套规则计算配置表-分类码配置屏幕
A1: 字段描述 | B1: 字段名 | C1: 字段逻辑 | D1: 字符类型 | E1: 基础查询 | F1: 高级查询 | G1: 查询方式 | H1: 是否可编辑 | I1: 备注
A2: 序号 | B2: =VLOOKUP($A2,字段列表!$A:$G,2,0) -> seqNo | C2: 自动赋值 | D2: =VLOOKUP($A2,字段列表!$A:$G,3,0) -> VARCHAR | E2: =VLOOKUP($A2,字段列表!$A:$G,5,0) -> - | F2: =VLOOKUP($A2,字段列表!$A:$G,6,0) -> - | G2: =VLOOKUP($A2,字段列表!$A:$G,7,0) -> - | H2: -
A3: 是否有效 | B3: =VLOOKUP($A3,字段列表!$A:$G,2,0) -> isActive | C3: 默认不勾选，勾选时，考虑对应条件的工单类型，表头列字段，支持一键全选，取消全选 | D3: =VLOOKUP($A3,字段列表!$A:$G,3,0) -> Boolean | E3: =VLOOKUP($A3,字段列表!$A:$G,5,0) -> Y | F3: =VLOOKUP($A3,字段列表!$A:$G,6,0) -> Y | G3: =VLOOKUP($A3,字段列表!$A:$G,7,0) -> BOOL | H3: Y
A4: 组织 | B4: =VLOOKUP($A4,字段列表!$A:$G,2,0) -> orgName | C4: 根据分类码，取分类码，对应"组织" | D4: =VLOOKUP($A4,字段列表!$A:$G,3,0) -> VARCHAR | E4: =VLOOKUP($A4,字段列表!$A:$G,5,0) -> Y | F4: =VLOOKUP($A4,字段列表!$A:$G,6,0) -> Y | G4: =VLOOKUP($A4,字段列表!$A:$G,7,0) -> SEL-1 | H4: Y
A5: 分类码 | B5: =VLOOKUP($A5,字段列表!$A:$G,2,0) -> categoryCode | C5: 配置值，支持勾选多个值，取EBS表"WIP_ACCOUNTING_CLASSES",值"CLASS_CODE"，根据所选配置组织，取出所有相应组织的"分类码" | D5: =VLOOKUP($A5,字段列表!$A:$G,3,0) -> VARCHAR | E5: =VLOOKUP($A5,字段列表!$A:$G,5,0) -> - | F5: =VLOOKUP($A5,字段列表!$A:$G,6,0) -> Y | G5: =VLOOKUP($A5,字段列表!$A:$G,7,0) -> SEL-2 | H5: Y

Sheet C1_3 齐套规则计算配置表-供给仓位配置
A1: 字段描述 | B1: 字段名 | C1: 字段逻辑 | D1: 字符类型 | E1: 基础查询 | F1: 高级查询 | G1: 查询方式 | H1: 是否可编辑 | I1: 备注
A2: 组织 | B2: =VLOOKUP($A2,字段列表!$A:$G,2,0) -> orgName | C2: 获取EBS表"MRP_SCHEDULE_DESIGNATORS"，字段"SCHEDULE_DESIGNATOR"对应的"组织" | D2: =VLOOKUP($A2,字段列表!$A:$G,3,0) -> VARCHAR | E2: =VLOOKUP($A2,字段列表!$A:$G,5,0) -> Y | F2: =VLOOKUP($A2,字段列表!$A:$G,6,0) -> Y | G2: =VLOOKUP($A2,字段列表!$A:$G,7,0) -> SEL-1 | H2: - | I2: 查询时必输
A3: EBS供给仓位配置 | B3: =VLOOKUP($A3,字段列表!$A:$G,2,0) -> calcSubInvNetValueName | C3: 根据配置条件"组织"，获取EBS对应组织的，所有"子库存净值名称SCHEDULE_DESIGNATOR"的数据，到该列表下 | D3: =VLOOKUP($A3,字段列表!$A:$G,3,0) -> VARCHAR | E3: =VLOOKUP($A3,字段列表!$A:$G,5,0) -> - | F3: =VLOOKUP($A3,字段列表!$A:$G,6,0) -> Y | G3: =VLOOKUP($A3,字段列表!$A:$G,7,0) -> SEL-2 | H3: Y | I3: 点击弹出，弹窗C1_3-1
A4: EBS供给仓位配置说明 | B4: =VLOOKUP($A4,字段列表!$A:$G,2,0) -> calcSubInvNetValueDesc | C4: 根据"子库存净值名称"，取值 | D4: =VLOOKUP($A4,字段列表!$A:$G,3,0) -> VARCHAR | E4: =VLOOKUP($A4,字段列表!$A:$G,5,0) -> - | F4: =VLOOKUP($A4,字段列表!$A:$G,6,0) -> - | G4: =VLOOKUP($A4,字段列表!$A:$G,7,0) -> - | H4: - | I4: -
A5: 是否有效 | B5: =VLOOKUP($A5,字段列表!$A:$G,2,0) -> isActive | C5: 勾选框， 是否生效，默认不勾选，决定时否启用该"EBS供给仓位配置" | D5: =VLOOKUP($A5,字段列表!$A:$G,3,0) -> Boolean | E5: =VLOOKUP($A5,字段列表!$A:$G,5,0) -> Y | F5: =VLOOKUP($A5,字段列表!$A:$G,6,0) -> Y | G5: =VLOOKUP($A5,字段列表!$A:$G,7,0) -> BOOL | H5: Y | I5: -

Sheet C1_3_1  齐套规则计算配置表-供给仓位配置-仓位选择
A1: 字段描述 | B1: 字段名 | C1: 字段逻辑 | D1: 字符类型 | E1: 基础查询 | F1: 高级查询 | G1: 查询方式 | H1: 是否可编辑 | I1: 备注
A2: 组织 | B2: =VLOOKUP($A2,字段列表!$A:$G,2,0) -> orgName | C2: 获取EBS表"MRP_SCHEDULE_DESIGNATORS"，字段"SCHEDULE_DESIGNATOR"对应的"组织" | D2: =VLOOKUP($A2,字段列表!$A:$G,3,0) -> VARCHAR | E2: =VLOOKUP($A2,字段列表!$A:$G,5,0) -> Y | F2: =VLOOKUP($A2,字段列表!$A:$G,6,0) -> Y | G2: =VLOOKUP($A2,字段列表!$A:$G,7,0) -> SEL-1 | H2: - | I2: -
A3: EBS供给仓位配置 | B3: =VLOOKUP($A3,字段列表!$A:$G,2,0) -> calcSubInvNetValueName | C3: 根据在屏幕"C1_3"选择行的字库存净值，带出 | D3: =VLOOKUP($A3,字段列表!$A:$G,3,0) -> VARCHAR | E3: =VLOOKUP($A3,字段列表!$A:$G,5,0) -> - | F3: =VLOOKUP($A3,字段列表!$A:$G,6,0) -> Y | G3: =VLOOKUP($A3,字段列表!$A:$G,7,0) -> SEL-2 | H3: - | I3: -
A4: EBS供给仓位配置说明 | B4: =VLOOKUP($A4,字段列表!$A:$G,2,0) -> calcSubInvNetValueDesc | C4: 根据"子库存净值名称"，取值 | D4: =VLOOKUP($A4,字段列表!$A:$G,3,0) -> VARCHAR | E4: =VLOOKUP($A4,字段列表!$A:$G,5,0) -> - | F4: =VLOOKUP($A4,字段列表!$A:$G,6,0) -> - | G4: =VLOOKUP($A4,字段列表!$A:$G,7,0) -> - | H4: - | I4: -
A5: 仓位名称 | B5: =VLOOKUP($A5,字段列表!$A:$G,2,0) -> locationCode | C5: 根据"子库存净值名称SCHEDULE_DESIGNATOR"，到EBS，取"MRP_SUB_INVENTORIES_V"内对应的仓位名称 | D5: =VLOOKUP($A5,字段列表!$A:$G,3,0) -> VARCHAR | E5: =VLOOKUP($A5,字段列表!$A:$G,5,0) -> Y | F5: =VLOOKUP($A5,字段列表!$A:$G,6,0) -> Y | G5: =VLOOKUP($A5,字段列表!$A:$G,7,0) -> SEL-2 | H5: Y | I5: -
A6: 仓位说明 | B6: =VLOOKUP($A6,字段列表!$A:$G,2,0) -> locationName | C6: 根据仓位编码，获取仓位说明 | D6: =VLOOKUP($A6,字段列表!$A:$G,3,0) -> VARCHAR | E6: =VLOOKUP($A6,字段列表!$A:$G,5,0) -> - | F6: =VLOOKUP($A6,字段列表!$A:$G,6,0) -> - | G6: =VLOOKUP($A6,字段列表!$A:$G,7,0) -> - | H6: - | I6: -
A7: 是否有效 | B7: =VLOOKUP($A7,字段列表!$A:$G,2,0) -> isActive | C7: 根据"子库存净值名称" AND “仓位编码”，取EBS"净数"，首次维护时，读取EBS的"净数"，后续在进行编辑和编辑时，不在读取。表头列字段，支持一键全选，取消全选 | D7: =VLOOKUP($A7,字段列表!$A:$G,3,0) -> Boolean | E7: =VLOOKUP($A7,字段列表!$A:$G,5,0) -> Y | F7: =VLOOKUP($A7,字段列表!$A:$G,6,0) -> Y | G7: =VLOOKUP($A7,字段列表!$A:$G,7,0) -> BOOL | H7: Y

Sheet C1_4 齐套规则计算配置表-供应商配置屏幕
A1: 字段描述 | B1: 字段名 | C1: 字段逻辑 | D1: 字符类型 | E1: 基础查询 | F1: 高级查询 | G1: 查询方式 | H1: 是否可编辑 | I1: 备注
A2: 组织 | B2: =VLOOKUP($A2,字段列表!$A:$G,2,0) -> orgName | C2: 根据查询时，选择"组织"查询出的，"供应商编码"对应的"组织"赋值 | D2: =VLOOKUP($A2,字段列表!$A:$G,3,0) -> VARCHAR | E2: =VLOOKUP($A2,字段列表!$A:$G,5,0) -> Y | F2: =VLOOKUP($A2,字段列表!$A:$G,6,0) -> Y | G2: =VLOOKUP($A2,字段列表!$A:$G,7,0) -> SEL-1 | H2: - | I2: 必输
A3: 供应商编码 | B3: =VLOOKUP($A3,字段列表!$A:$G,2,0) -> supplierCode | C3: 根据配置的组织，取EBS相应组织，表"AP_SUPPLIERS"，字段"VENDOR_TYPE_LOOKUP_CODE"=委外供应商的，字段"SEGMENT1"， | D3: =VLOOKUP($A3,字段列表!$A:$G,3,0) -> VARCHAR | E3: Y | F3: =VLOOKUP($A3,字段列表!$A:$G,6,0) -> Y | G3: =VLOOKUP($A3,字段列表!$A:$G,7,0) -> SEL-2 | H3: - | I3: -
A4: 供应商简称 | B4: =VLOOKUP($A4,字段列表!$A:$G,2,0) -> supplierDesc | C4: 根据"供应商编码SEGMENT1"字段到表"AP_SUPPLIERS"取"VENDOR_NAME"， | D4: =VLOOKUP($A4,字段列表!$A:$G,3,0) -> VARCHAR | E4: =VLOOKUP($A4,字段列表!$A:$G,5,0) -> - | F4: =VLOOKUP($A4,字段列表!$A:$G,6,0) -> - | G4: =VLOOKUP($A4,字段列表!$A:$G,7,0) -> - | H4: - | I4: -
A5: 是否有效 | B5: =VLOOKUP($A5,字段列表!$A:$G,2,0) -> isActive | C5: 勾选框， 默认不勾选，按勾选，决定是否考虑，表头列字段，支持一键全选，取消全选 | D5: =VLOOKUP($A5,字段列表!$A:$G,3,0) -> Boolean | E5: =VLOOKUP($A5,字段列表!$A:$G,5,0) -> Y | F5: =VLOOKUP($A5,字段列表!$A:$G,6,0) -> Y | G5: =VLOOKUP($A5,字段列表!$A:$G,7,0) -> BOOL | H5: Y | I5: -

Sheet C1_5 齐套规则计算配置表-工单状态配置屏幕
A1: 字段描述 | B1: 字段名 | C1: 字段逻辑 | D1: 字符类型 | E1: 基础查询 | F1: 高级查询 | G1: 查询方式 | H1: 是否可编辑 | I1: 备注
A2: 工单状态 | B2: =VLOOKUP($A2,字段列表!$A:$G,2,0) -> workOrderStatus | C2: 取EBS select lu.meaning,LU.LOOKUP_CODE from fnd_lookup_values lu WHERE lu.language = 'ZHS' and lu.lookup_type = 'WIP_JOB_STATUS' | D2: =VLOOKUP($A2,字段列表!$A:$G,3,0) -> VARCHAR | E2: =VLOOKUP($A2,字段列表!$A:$G,5,0) -> - | F2: =VLOOKUP($A2,字段列表!$A:$G,6,0) -> Y | G2: =VLOOKUP($A2,字段列表!$A:$G,7,0) -> SEL-2 | H2: - | I2: -
A3: 是否有效 | B3: =VLOOKUP($A3,字段列表!$A:$G,2,0) -> isActive | C3: 勾选框， 默认不勾选，按勾选，决定是否考虑，表头列字段，支持一键全选，取消全选 | D3: =VLOOKUP($A3,字段列表!$A:$G,3,0) -> Boolean | E3: =VLOOKUP($A3,字段列表!$A:$G,5,0) -> Y | F3: =VLOOKUP($A3,字段列表!$A:$G,6,0) -> Y | G3: =VLOOKUP($A3,字段列表!$A:$G,7,0) -> BOOL | H3: Y | I3: -

Sheet C2 工单齐套优先级维护表
A1: 序号 | B1: 字段描述 | C1: 字段名 | D1: 字段逻辑 | E1: 字符类型 | F1: 基础查询 | G1: 高级查询 | H1: 查询方式 | I1: 是否可编辑 | J1: 备注
A2: 1 | B2: 组织 | C2: orgName | D2: 通过"工单号"获取 | E2: VARCHAR | F2: Y | G2: Y | H2: SEL_2 | I2: - | J2: 查询时必填
A3: 2 | B3: 订单编号 | C3: orderNo | D3: 通过"工单号"获取，取OMS的工单头表，通过工单号，关联订单号 | E3: VARCHAR | F3: Y | G3: Y | H3: TXT_1 | I3: -
A4: 3 | B4: 订单创建日期 | C4: orderCreateDate | D4: 通过"订单编号"获取 | E4: Date | F4: _ | G4: Y | H4: DATA | I4: -
A5: 4 | B5: 订单创建人 | C5: orderCreator | D5: 通过"订单编号"获取 | E5: VARCHAR | F5: _ | G5: Y | H5: TXT_2 | I5: -
A6: 5 | B6: 订单类型 | C6: orderType | D6: 通过"订单编号"获取 | E6: VARCHAR | F6: Y | G6: Y | H6: SEL_2 | I6: -
A7: 6 | B7: 产品线 | C7: productLine | D7: 通过"订单编号"获取 | E7: VARCHAR | F7: _ | G7: Y | H7: SEL_2 | I7: -
A8: 7 | B8: 料号 | C8: materialCode | D8: 通过"工单号"获取 | E8: VARCHAR | F8: Y | G8: Y | H8: TXT_1 | I8: -
A9: 8 | B9: 叠die数 | C9: dieStackQty | D9: 到EBS获取物料主数据信息，通过"工单号-料号"获取 | E9: VARCHAR | F9: _ | G9: Y | H9: TXT_2 | I9: -
A10: 9 | B10: 产品类别 | C10: productCategory | D10: 到EBS获取物料主数据信息，通过"工单号-料号"获取 | E10: VARCHAR | F10: _ | G10: Y | H10: SEL_2 | I10: -
A11: 10 | B11: 容量 | C11: capacity | D11: 到EBS获取物料主数据信息，通过"工单号-料号"获取 | E11: VARCHAR | F11: _ | G11: Y | H11: SEL_2 | I11: -
A12: 11 | B12: 产品PN | C12: productPn | D12: 到EBS获取物料主数据信息，通过"工单号-料号"获取 | E12: VARCHAR | F12: _ | G12: Y | H12: TXT_2 | I12: -
A13: 12 | B13: 说明 | C13: materialDes | D13: 到EBS获取物料主数据信息，通过"工单号-料号"获取 | E13: VARCHAR | F13: _ | G13: Y | H13: TXT_2 | I13: -
A14: 13 | B14: 下单数量 | C14: orderQty | D14: 通过"订单编号"获取 | E14: VARCHAR | F14: _ | G14: Y | H14: NUM | I14: -
... A17: 16 | B17: 工单状态 | C17: workOrderStatus | D17: 通过"工单号"获取 | E17: VARCHAR | F17: _ | G17: Y | H17: SEL_2 | I17: -
A18: 17 | B18: 工单号 | C18: workOrderNo | D18: 通过接口，取EBS工单信息，按组织&"工单状态" = "已发放" AND "未发放"的单据 | E18: VARCHAR | F18: Y | G18: Y | H18: TXT_1 | I18: - | J18: KEY
A19: 18 | B19: 工单优先级 | C19: workOrderPriority | D19: 在"工单优先级维护"表内通过"工单号"获取 | E19: INT | F19: Y | G19: Y | H19: NUM | I19: -
A20: 19 | B20: 转单人 | C20: transferBy | D20: 通过"工单号"获取 | E20: VARCHAR | F20: _ | G20: Y | H20: TXT_2 | I20: -
A21: 20 | B21: 转单时间 | C21: transferTime | D21: 通过"工单号"获取 | E21: Date | F21: _ | G21: Y | H21: DATA | I21: - | J21: 默认近30天
A22: 21 | B22: 转单数量 | C22: transferQty | D22: 通过"工单号"获取 | E22: VARCHAR | F22: _ | G22: Y | H22: NUM | I22: -
A23: 22 | B23: 已完工数量 | C23: completedQty | D23: 通过"工单号"获取 | E23: VARCHAR | F23: _ | G23: Y | H23: NUM | I23: -
A24: 23 | B24: 报废数量 | C24: scrapQty | D24: 通过"工单号"获取 | E24: VARCHAR | F24: _ | G24: Y | H24: NUM | I24: -
A25: 24 | B25: 未完成数量 | C25: incompleteQty | D25: 通过"工单号"获取 | E25: VARCHAR | F25: _ | G25: Y | H25: NUM | I25: -
A26: 25 | B26: 供应商编码 | C26: supplierCode | D26: 通过"工单号"获取 | E26: VARCHAR | F26: _ | G26: Y | H26: SEL_2 | I26: -
A27: 26 | B27: 供应商简称 | C27: supplierDesc | D27: 通过"工单号"获取 | E27: VARCHAR | F27: _ | G27: _ | H27: _ | I27: -
A28: 27 | B28: 要求齐料日期（起始(MRP)日期） | C28: requiredMaterialDate | D28: 获取 工单号-起始(MRP)日期M_SCHEDULED_START_DATE | E28: Date | F28: _ | G28: Y | H28: DATA | I28: -
A29: 28 | B29: 工单优先级 | C29: workOrderPriority | D29: 人工维护 | E29: INT | F29: Y | G29: Y | H29: NUM | I29: Y | J29: 固定在表格区域右侧

Sheet C3 组件责任方配置
A1: 字段描述 | B1: 字段名 | C1: 字符类型 | D1: 字段逻辑 | E1: 字符类型 | F1: 基础查询 | G1: 高级查询 | H1: 查询方式 | I1: 是否可编辑 | J1: 备注
A2: 零部件类别 | B2: N/A | C2: =VLOOKUP($A2,字段列表!$A:$G,2,0) -> componentCategory | D2: 取EBS物料主数据的零部件类别，下拉选择，单选 | E2: =VLOOKUP($A2,字段列表!$A:$G,3,0) -> VARCHAR | F2: Y | G2: - | H2: SEL-1 | I2: Y | J2: -
A3: 组件类别 | B3: N/A | C3: =VLOOKUP($A3,字段列表!$A:$G,2,0) -> #N/A | D3: 人工维护 | E3: =VLOOKUP($A3,字段列表!$A:$G,3,0) -> #N/A | F3: Y | G3: - | H3: #N/A | I3: Y | J3: -
A4: 组件责任人 | B4: N/A | C4: =VLOOKUP($A4,字段列表!$A:$G,2,0) -> #N/A | D4: 人工维护 | E4: =VLOOKUP($A4,字段列表!$A:$G,3,0) -> #N/A | F4: Y | G4: - | H4: #N/A | I4: Y | J4: -
A5: 创建时间 | B5: N/A | C5: =VLOOKUP($A5,字段列表!$A:$G,2,0) -> #N/A | D5: 系统自动赋值 | E5: =VLOOKUP($A5,字段列表!$A:$G,3,0) -> #N/A | G5: - | H5: #N/A | I5: - | J5: -
A6: 修改时间 | B6: N/A | C6: =VLOOKUP($A6,字段列表!$A:$G,2,0) -> #N/A | D6: 系统自动赋值 | E6: =VLOOKUP($A6,字段列表!$A:$G,3,0) -> #N/A | G6: - | H6: #N/A | I6: - | J6: -
A7: 修改人 | B7: N/A | C7: =VLOOKUP($A7,字段列表!$A:$G,2,0) -> #N/A | D7: 系统自动赋值 | E7: =VLOOKUP($A7,字段列表!$A:$G,3,0) -> #N/A | F7: Y | G7: - | H7: #N/A | I7: - | J7: -

Sheet M1 工单齐套明细
A1: 字段描述 | B1: 字段名 | C1: 字段逻辑 | D1: 字符类型 | E1: 基础查询 | F1: 高级查询 | G1: 查询方式 | H1: 备注
A2: 序号 | B2: =VLOOKUP(A2,字段列表!$A:$G,2,0) -> seqNo | C2: 按照行项数自动赋值 | D2: =VLOOKUP($A2,字段列表!$A:$G,3,0) -> VARCHAR | E2: =VLOOKUP($A2,字段列表!$A:$G,5,0) -> - | F2: =VLOOKUP($A2,字段列表!$A:$G,6,0) -> - | G2: =VLOOKUP($A2,字段列表!$A:$G,7,0) -> -
A3: 齐套版本 | B3: =VLOOKUP(A3,字段列表!$A:$G,2,0) -> VerSion | C3: 配置编码获取&运行时间 | D3: =VLOOKUP($A3,字段列表!$A:$G,3,0) -> INT | E3: =VLOOKUP($A3,字段列表!$A:$G,5,0) -> - | F3: =VLOOKUP($A3,字段列表!$A:$G,6,0) -> Y | G3: =VLOOKUP($A3,字段列表!$A:$G,7,0) -> NUM
A4: 配置编码 | B4: =VLOOKUP(A4,字段列表!$A:$G,2,0) -> configCode | C4: 运行时根据选择的配置编码，赋值 | D4: =VLOOKUP($A4,字段列表!$A:$G,3,0) -> VARCHAR | E4: =VLOOKUP($A4,字段列表!$A:$G,5,0) -> Y | F4: =VLOOKUP($A4,字段列表!$A:$G,6,0) -> Y | G4: =VLOOKUP($A4,字段列表!$A:$G,7,0) -> TXT-1 | H4: 查询条件必填
A5: 运行时间 | B5: =VLOOKUP(A5,字段列表!$A:$G,2,0) -> runTime | C5: 取"配置编码"运行齐套的时间赋值 | D5: =VLOOKUP($A5,字段列表!$A:$G,3,0) -> Date | E5: =VLOOKUP($A5,字段列表!$A:$G,5,0) -> - | F5: =VLOOKUP($A5,字段列表!$A:$G,6,0) -> Y | G5: =VLOOKUP($A5,字段列表!$A:$G,7,0) -> DATA
A6: 最后运行人 | B6: =VLOOKUP(A6,字段列表!$A:$G,2,0) -> lastRunBy | C6: 根据运行的账户赋值 | D6: =VLOOKUP($A6,字段列表!$A:$G,3,0) -> VARCHAR | E6: =VLOOKUP($A6,字段列表!$A:$G,5,0) -> - | F6: =VLOOKUP($A6,字段列表!$A:$G,6,0) -> Y | G6: =VLOOKUP($A6,字段列表!$A:$G,7,0) -> TXT-2
A7: 组织 | B7: =VLOOKUP(A7,字段列表!$A:$G,2,0) -> orgName | C7: 通过"工单号"获取 | D7: =VLOOKUP($A7,字段列表!$A:$G,3,0) -> VARCHAR | E7: =VLOOKUP($A7,字段列表!$A:$G,5,0) -> Y | F7: =VLOOKUP($A7,字段列表!$A:$G,6,0) -> Y | G7: =VLOOKUP($A7,字段列表!$A:$G,7,0) -> SEL-1
A8: 订单编号 | B8: =VLOOKUP(A8,字段列表!$A:$G,2,0) -> orderNo | C8: 通过"工单号"获取，取OMS的工单头表，通过工单号，关联订单号 | D8: =VLOOKUP($A8,字段列表!$A:$G,3,0) -> VARCHAR | E8: =VLOOKUP($A8,字段列表!$A:$G,5,0) -> Y | F8: =VLOOKUP($A8,字段列表!$A:$G,6,0) -> Y | G8: =VLOOKUP($A8,字段列表!$A:$G,7,0) -> TXT-1
A9: 订单创建日期 | B9: =VLOOKUP(A9,字段列表!$A:$G,2,0) -> orderCreateDate | C9: 通过"订单编号"获取 | D9: =VLOOKUP($A9,字段列表!$A:$G,3,0) -> Date | E9: =VLOOKUP($A9,字段列表!$A:$G,5,0) -> - | F9: =VLOOKUP($A9,字段列表!$A:$G,6,0) -> Y | G9: =VLOOKUP($A9,字段列表!$A:$G,7,0) -> DATA
A10: 订单创建人 | B10: =VLOOKUP(A10,字段列表!$A:$G,2,0) -> orderCreator | C10: 通过"订单编号"获取 | D10: =VLOOKUP($A10,字段列表!$A:$G,3,0) -> VARCHAR | E10: =VLOOKUP($A10,字段列表!$A:$G,5,0) -> - | F10: =VLOOKUP($A10,字段列表!$A:$G,6,0) -> Y | G10: =VLOOKUP($A10,字段列表!$A:$G,7,0) -> TXT-2
A11: 订单类型 | B11: =VLOOKUP(A11,字段列表!$A:$G,2,0) -> orderType | C11: 通过"订单编号"获取 | D11: =VLOOKUP($A11,字段列表!$A:$G,3,0) -> VARCHAR | E11: =VLOOKUP($A11,字段列表!$A:$G,5,0) -> Y | F11: =VLOOKUP($A11,字段列表!$A:$G,6,0) -> Y | G11: =VLOOKUP($A11,字段列表!$A:$G,7,0) -> SEL-2
A12: 产品线 | B12: =VLOOKUP(A12,字段列表!$A:$G,2,0) -> productLine | C12: 通过"订单编号"获取 | D12: =VLOOKUP($A12,字段列表!$A:$G,3,0) -> VARCHAR | E12: =VLOOKUP($A12,字段列表!$A:$G,5,0) -> - | F12: =VLOOKUP($A12,字段列表!$A:$G,6,0) -> Y | G12: =VLOOKUP($A12,字段列表!$A:$G,7,0) -> SEL-2
A13: 料号 | B13: =VLOOKUP(A13,字段列表!$A:$G,2,0) -> materialCode | C13: 通过"工单号"获取 | D13: =VLOOKUP($A13,字段列表!$A:$G,3,0) -> VARCHAR | E13: =VLOOKUP($A13,字段列表!$A:$G,5,0) -> Y | F13: =VLOOKUP($A13,字段列表!$A:$G,6,0) -> Y | G13: =VLOOKUP($A13,字段列表!$A:$G,7,0) -> TXT-1
A14: 说明 | B14: =VLOOKUP(A14,字段列表!$A:$G,2,0) -> materialDes | C14: 通过"工单号"获取 | D14: =VLOOKUP($A14,字段列表!$A:$G,3,0) -> VARCHAR | E14: =VLOOKUP($A14,字段列表!$A:$G,5,0) -> - | F14: =VLOOKUP($A14,字段列表!$A:$G,6,0) -> Y | G14: =VLOOKUP($A14,字段列表!$A:$G,7,0) -> TXT-2
A15: 叠die数 | B15: =VLOOKUP(A15,字段列表!$A:$G,2,0) -> dieStackQty | C15: 通过"工单号-料号",获取 | D15: =VLOOKUP($A15,字段列表!$A:$G,3,0) -> VARCHAR | E15: =VLOOKUP($A15,字段列表!$A:$G,5,0) -> - | F15: =VLOOKUP($A15,字段列表!$A:$G,6,0) -> Y | G15: =VLOOKUP($A15,字段列表!$A:$G,7,0) -> TXT-2
A16: 产品类别 | B16: =VLOOKUP(A16,字段列表!$A:$G,2,0) -> productCategory | C16: 通过"工单号"获取 | D16: =VLOOKUP($A16,字段列表!$A:$G,3,0) -> VARCHAR | E16: =VLOOKUP($A16,字段列表!$A:$G,5,0) -> - | F16: =VLOOKUP($A16,字段列表!$A:$G,6,0) -> Y | G16: =VLOOKUP($A16,字段列表!$A:$G,7,0) -> SEL-2
... A23: 工单号 | B23: =VLOOKUP(A23,字段列表!$A:$G,2,0) -> workOrderNo | C23: 在运行齐套时，根据"配置表-齐套规则计算配置表"按照配置条件在，取EBS 表"wip_discrete_jobs_v "对应符合配置条件的工单， 增加链接，通过点工单号跳转到"工单齐套-工单详情"，并筛选相应的数据 | D23: =VLOOKUP($A23,字段列表!$A:$G,3,0) -> VARCHAR | E23: =VLOOKUP($A23,字段列表!$A:$G,5,0) -> Y | F23: =VLOOKUP($A23,字段列表!$A:$G,6,0) -> Y | G23: =VLOOKUP($A23,字段列表!$A:$G,7,0) -> TXT-1
A24: 工单优先级 | B24: =VLOOKUP(A24,字段列表!$A:$G,2,0) -> workOrderPriority | C24: 在"工单优先级维护"表内通过"工单号"获取 | D24: =VLOOKUP($A24,字段列表!$A:$G,3,0) -> INT | E24: - | F24: =VLOOKUP($A24,字段列表!$A:$G,6,0) -> Y | G24: =VLOOKUP($A24,字段列表!$A:$G,7,0) -> NUM
A25: 转单人 | B25: =VLOOKUP(A25,字段列表!$A:$G,2,0) -> transferBy | C25: 通过"工单号"获取 | D25: =VLOOKUP($A25,字段列表!$A:$G,3,0) -> VARCHAR | E25: =VLOOKUP($A25,字段列表!$A:$G,5,0) -> - | F25: =VLOOKUP($A25,字段列表!$A:$G,6,0) -> Y | G25: =VLOOKUP($A25,字段列表!$A:$G,7,0) -> TXT-2
A26: 转单时间 | B26: =VLOOKUP(A26,字段列表!$A:$G,2,0) -> transferTime | C26: 通过"工单号"获取 | D26: =VLOOKUP($A26,字段列表!$A:$G,3,0) -> Date | E26: =VLOOKUP($A26,字段列表!$A:$G,5,0) -> - | F26: =VLOOKUP($A26,字段列表!$A:$G,6,0) -> Y | G26: =VLOOKUP($A26,字段列表!$A:$G,7,0) -> DATA
A27: 转单数量 | B27: =VLOOKUP(A27,字段列表!$A:$G,2,0) -> transferQty | C27: 通过"工单号"获取 | D27: =VLOOKUP($A27,字段列表!$A:$G,3,0) -> VARCHAR | E27: =VLOOKUP($A27,字段列表!$A:$G,5,0) -> - | F27: =VLOOKUP($A27,字段列表!$A:$G,6,0) -> Y | G27: =VLOOKUP($A27,字段列表!$A:$G,7,0) -> NUM
A28: 已完工数量 | B28: =VLOOKUP(A28,字段列表!$A:$G,2,0) -> completedQty | C28: 通过"工单号"获取 | D28: =VLOOKUP($A28,字段列表!$A:$G,3,0) -> VARCHAR | E28: =VLOOKUP($A28,字段列表!$A:$G,5,0) -> - | F28: =VLOOKUP($A28,字段列表!$A:$G,6,0) -> Y | G28: =VLOOKUP($A28,字段列表!$A:$G,7,0) -> NUM
A29: 报废数量 | B29: =VLOOKUP(A29,字段列表!$A:$G,2,0) -> scrapQty | C29: 通过"工单号"获取 | D29: =VLOOKUP($A29,字段列表!$A:$G,3,0) -> VARCHAR | E29: =VLOOKUP($A29,字段列表!$A:$G,5,0) -> - | F29: =VLOOKUP($A29,字段列表!$A:$G,6,0) -> Y | G29: =VLOOKUP($A29,字段列表!$A:$G,7,0) -> NUM
A30: 未完成数量 | B30: =VLOOKUP(A30,字段列表!$A:$G,2,0) -> incompleteQty | C30: 通过"工单号"获取 | D30: =VLOOKUP($A30,字段列表!$A:$G,3,0) -> VARCHAR | E30: =VLOOKUP($A30,字段列表!$A:$G,5,0) -> - | F30: =VLOOKUP($A30,字段列表!$A:$G,6,0) -> Y | G30: =VLOOKUP($A30,字段列表!$A:$G,7,0) -> NUM
A31: 供应商编码 | B31: =VLOOKUP(A31,字段列表!$A:$G,2,0) -> supplierCode | C31: 通过"工单号"获取 | D31: =VLOOKUP($A31,字段列表!$A:$G,3,0) -> VARCHAR | E31: =VLOOKUP($A31,字段列表!$A:$G,5,0) -> - | F31: =VLOOKUP($A31,字段列表!$A:$G,6,0) -> Y | G31: =VLOOKUP($A31,字段列表!$A:$G,7,0) -> SEL-2
A32: 供应商简称 | B32: =VLOOKUP(A32,字段列表!$A:$G,2,0) -> supplierDesc | C32: 通过"工单号"获取 | D32: =VLOOKUP($A32,字段列表!$A:$G,3,0) -> VARCHAR | E32: =VLOOKUP($A32,字段列表!$A:$G,5,0) -> - | F32: =VLOOKUP($A32,字段列表!$A:$G,6,0) -> - | G32: =VLOOKUP($A32,字段列表!$A:$G,7,0) -> -
A33: 要求齐料日期（起始(MRP)日期） | B33: =VLOOKUP(A33,字段列表!$A:$G,2,0) -> requiredMaterialDate | C33: 获取 工单号-起始(MRP)日期M_SCHEDULED_START_DATE | D33: =VLOOKUP($A33,字段列表!$A:$G,3,0) -> Date | E33: =VLOOKUP($A33,字段列表!$A:$G,5,0) -> - | F33: =VLOOKUP($A33,字段列表!$A:$G,6,0) -> Y | G33: =VLOOKUP($A33,字段列表!$A:$G,7,0) -> DATA
A34: 组件物料 | B34: =VLOOKUP(A34,字段列表!$A:$G,2,0) -> componentMaterialCode | C34: 通过"工单号"，取表EBS"wip_requirement_operations"工单行数据 增加链接，通过点组件料号跳转到"工单齐套-物料详情"，并筛选相应的数据 | D34: =VLOOKUP($A34,字段列表!$A:$G,3,0) -> VARCHAR | E34: =VLOOKUP($A34,字段列表!$A:$G,5,0) -> Y | F34: =VLOOKUP($A34,字段列表!$A:$G,6,0) -> Y | G34: =VLOOKUP($A34,字段列表!$A:$G,7,0) -> TXT-1
A35: 组件物料描述 | B35: =VLOOKUP(A35,字段列表!$A:$G,2,0) -> componentMaterialDesc | C35: 通过 组件物料-说明 | D35: =VLOOKUP($A35,字段列表!$A:$G,3,0) -> VARCHAR | E35: =VLOOKUP($A35,字段列表!$A:$G,5,0) -> - | F35: =VLOOKUP($A35,字段列表!$A:$G,6,0) -> Y | G35: =VLOOKUP($A35,字段列表!$A:$G,7,0) -> TXT-2
A36: LT | B36: =VLOOKUP(A36,字段列表!$A:$G,2,0) -> componentLeadTime | C36: 通过组件料号，获取EBS"固定供应天数 FIXED_DAYS_SUPPLY_MIR' | D36: =VLOOKUP($A36,字段列表!$A:$G,3,0) -> VARCHAR | E36: =VLOOKUP($A36,字段列表!$A:$G,5,0) -> - | F36: =VLOOKUP($A36,字段列表!$A:$G,6,0) -> Y | G36: =VLOOKUP($A36,字段列表!$A:$G,7,0) -> NUM
... A39: 组件责任方 | B39: =VLOOKUP(A39,字段列表!$A:$G,2,0) -> componentResponsibleParty | C39: 配置表"C3 组件责任方配置"，通过"零部件类别"，取对应"组件分类-组件责任方" | D39: =VLOOKUP($A39,字段列表!$A:$G,3,0) -> VARCHAR | E39: =VLOOKUP($A39,字段列表!$A:$G,5,0) -> Y | F39: =VLOOKUP($A39,字段列表!$A:$G,6,0) -> Y | G39: =VLOOKUP($A39,字段列表!$A:$G,7,0) -> TXT-2
A40: 是否资源 | B40: =VLOOKUP(A40,字段列表!$A:$G,2,0) -> isResource | C40: 根据组件编码，取EBS物料主数据，字段"IS_RESOURCES_FLAG" Y为产品管控物料，N为非产品线管控物料 | D40: =VLOOKUP($A40,字段列表!$A:$G,3,0) -> Boolean | E40: =VLOOKUP($A40,字段列表!$A:$G,5,0) -> - | F40: =VLOOKUP($A40,字段列表!$A:$G,6,0) -> Y | G40: =VLOOKUP($A40,字段列表!$A:$G,7,0) -> SEL-1 | H40: Y/N
A41: 单位用量 | B41: =VLOOKUP(A41,字段列表!$A:$G,2,0) -> unitUsage | C41: 获取 工单号-组件料号-单位用量QUANTITY_PER_ASSEMBLY(每个装配件) | D41: =VLOOKUP($A41,字段列表!$A:$G,3,0) -> VARCHAR | E41: =VLOOKUP($A41,字段列表!$A:$G,5,0) -> - | F41: =VLOOKUP($A41,字段列表!$A:$G,6,0) -> Y | G41: =VLOOKUP($A41,字段列表!$A:$G,7,0) -> NUM
A42: 必需 | B42: =VLOOKUP(A42,字段列表!$A:$G,2,0) -> isRequired | C42: 获取 工单号-组件料号-必需REQ_QUANT_DIS | D42: =VLOOKUP($A42,字段列表!$A:$G,3,0) -> VARCHAR | E42: =VLOOKUP($A42,字段列表!$A:$G,5,0) -> - | F42: =VLOOKUP($A42,字段列表!$A:$G,6,0) -> Y | G42: =VLOOKUP($A42,字段列表!$A:$G,7,0) -> NUM
A43: 产出率 | B43: =VLOOKUP(A43,字段列表!$A:$G,2,0) -> yieldRate | C43: 获取 工单号-组件料号-产出率COMPONENT_YIELD_FACTOR | D43: =VLOOKUP($A43,字段列表!$A:$G,3,0) -> VARCHAR | E43: =VLOOKUP($A43,字段列表!$A:$G,5,0) -> - | F43: =VLOOKUP($A43,字段列表!$A:$G,6,0) -> Y | G43: =VLOOKUP($A43,字段列表!$A:$G,7,0) -> NUM
A44: 已发料量 | B44: =VLOOKUP(A44,字段列表!$A:$G,2,0) -> issuedQty | C44: 获取 工单号-组件料号-已发料量QUANTITY_ISSUED | D44: =VLOOKUP($A44,字段列表!$A:$G,3,0) -> VARCHAR | E44: =VLOOKUP($A44,字段列表!$A:$G,5,0) -> - | F44: =VLOOKUP($A44,字段列表!$A:$G,6,0) -> Y | G44: =VLOOKUP($A44,字段列表!$A:$G,7,0) -> NUM
A45: 未发料数量 | B45: =VLOOKUP(A45,字段列表!$A:$G,2,0) -> unIssuedQty | C45: 获取 工单号-组件料号-未完成QUANTITY_OPEN | D45: =VLOOKUP($A45,字段列表!$A:$G,3,0) -> VARCHAR | E45: =VLOOKUP($A45,字段列表!$A:$G,5,0) -> - | F45: =VLOOKUP($A45,字段列表!$A:$G,6,0) -> Y | G45: =VLOOKUP($A45,字段列表!$A:$G,7,0) -> NUM
A46: 可用量 | B46: =VLOOKUP(A46,字段列表!$A:$G,2,0) -> availableQty | C46: 获取 工单号-组件料号-可用量QOH | D46: =VLOOKUP($A46,字段列表!$A:$G,3,0) -> VARCHAR | E46: =VLOOKUP($A46,字段列表!$A:$G,5,0) -> - | F46: =VLOOKUP($A46,字段列表!$A:$G,6,0) -> Y | G46: =VLOOKUP($A46,字段列表!$A:$G,7,0) -> NUM
A47: 现存数量 | B47: =VLOOKUP(A47,字段列表!$A:$G,2,0) -> onHandQty | C47: 取通过"组件料号"&"组织"，取EBS 的"现存数量"LIMIT_ONHAND_QUANTITY字段 | D47: =VLOOKUP($A47,字段列表!$A:$G,3,0) -> VARCHAR | E47: =VLOOKUP($A47,字段列表!$A:$G,5,0) -> - | F47: =VLOOKUP($A47,字段列表!$A:$G,6,0) -> Y | G47: =VLOOKUP($A47,字段列表!$A:$G,7,0) -> NUM
A48: 发料仓 | B48: =VLOOKUP(A48,字段列表!$A:$G,2,0) -> issueWarehouse | C48: 通过"工单号"&“组件料号”获取(子库存SUPPLY_SUBINVENTORY) | D48: =VLOOKUP($A48,字段列表!$A:$G,3,0) -> VARCHAR | E48: =VLOOKUP($A48,字段列表!$A:$G,5,0) -> - | F48: =VLOOKUP($A48,字段列表!$A:$G,6,0) -> Y | G48: =VLOOKUP($A48,字段列表!$A:$G,7,0) -> SEL-2
...

Sheet M1_1 WO工单信息表
A1: 字段描述 | B1: 字段名 | C1: 字段逻辑 | D1: 字符类型 | E1: 基础查询 | F1: 高级查询 | G1: 查询方式 | H1: 是否可编辑 | I1: 备注
A2: 组织 | B2: =VLOOKUP(A2,字段列表!$A:$G,2,0) -> orgName | C2: 通过"工单号"获取 | D2: =VLOOKUP($A2,字段列表!$A:$G,3,0) -> VARCHAR | E2: =VLOOKUP($A2,字段列表!$A:$G,5,0) -> Y | F2: =VLOOKUP($A2,字段列表!$A:$G,6,0) -> Y | G2: =VLOOKUP($A2,字段列表!$A:$G,7,0) -> SEL-1 | H2: N
A3: 订单编号 | B3: =VLOOKUP(A3,字段列表!$A:$G,2,0) -> orderNo | C3: 通过"工单号"获取，取OMS的工单头表，通过工单号，关联订单号 | D3: =VLOOKUP($A3,字段列表!$A:$G,3,0) -> VARCHAR | E3: =VLOOKUP($A3,字段列表!$A:$G,5,0) -> Y | F3: =VLOOKUP($A3,字段列表!$A:$G,6,0) -> Y | G3: =VLOOKUP($A3,字段列表!$A:$G,7,0) -> TXT-1 | H3: N
A4: 订单创建日期 | B4: =VLOOKUP(A4,字段列表!$A:$G,2,0) -> orderCreateDate | C4: 通过"订单编号"获取 | D4: =VLOOKUP($A4,字段列表!$A:$G,3,0) -> Date | E4: =VLOOKUP($A4,字段列表!$A:$G,5,0) -> - | F4: =VLOOKUP($A4,字段列表!$A:$G,6,0) -> Y | G4: =VLOOKUP($A4,字段列表!$A:$G,7,0) -> DATA | H4: N
A5: 订单创建人 | B5: =VLOOKUP(A5,字段列表!$A:$G,2,0) -> orderCreator | C5: 通过"订单编号"获取 | D5: =VLOOKUP($A5,字段列表!$A:$G,3,0) -> VARCHAR | E5: =VLOOKUP($A5,字段列表!$A:$G,5,0) -> - | F5: =VLOOKUP($A5,字段列表!$A:$G,6,0) -> Y | G5: =VLOOKUP($A5,字段列表!$A:$G,7,0) -> TXT-2 | H5: N
A6: 订单类型 | B6: =VLOOKUP(A6,字段列表!$A:$G,2,0) -> orderType | C6: 通过"订单编号"获取 | D6: =VLOOKUP($A6,字段列表!$A:$G,3,0) -> VARCHAR | E6: =VLOOKUP($A6,字段列表!$A:$G,5,0) -> Y | F6: =VLOOKUP($A6,字段列表!$A:$G,6,0) -> Y | G6: =VLOOKUP($A6,字段列表!$A:$G,7,0) -> SEL-2 | H6: N
A7: 产品线 | B7: =VLOOKUP(A7,字段列表!$A:$G,2,0) -> productLine | C7: 通过"订单编号"获取 | D7: =VLOOKUP($A7,字段列表!$A:$G,3,0) -> VARCHAR | E7: =VLOOKUP($A7,字段列表!$A:$G,5,0) -> - | F7: =VLOOKUP($A7,字段列表!$A:$G,6,0) -> Y | G7: =VLOOKUP($A7,字段列表!$A:$G,7,0) -> SEL-2 | H7: N
A8: 料号 | B8: =VLOOKUP(A8,字段列表!$A:$G,2,0) -> materialCode | C8: 通过"工单号"获取 | D8: =VLOOKUP($A8,字段列表!$A:$G,3,0) -> VARCHAR | E8: =VLOOKUP($A8,字段列表!$A:$G,5,0) -> Y | F8: =VLOOKUP($A8,字段列表!$A:$G,6,0) -> Y | G8: =VLOOKUP($A8,字段列表!$A:$G,7,0) -> TXT-1 | H8: N
A9: 说明 | B9: =VLOOKUP(A9,字段列表!$A:$G,2,0) -> materialDes | C9: 通过"工单号"获取 | D9: =VLOOKUP($A9,字段列表!$A:$G,3,0) -> VARCHAR | E9: =VLOOKUP($A9,字段列表!$A:$G,5,0) -> - | F9: =VLOOKUP($A9,字段列表!$A:$G,6,0) -> Y | G9: =VLOOKUP($A9,字段列表!$A:$G,7,0) -> TXT-2 | H9: N
A10: 叠die数 | B10: =VLOOKUP(A10,字段列表!$A:$G,2,0) -> dieStackQty | C10: 通过"工单号-料号",获取 | D10: =VLOOKUP($A10,字段列表!$A:$G,3,0) -> VARCHAR | E10: =VLOOKUP($A10,字段列表!$A:$G,5,0) -> - | F10: =VLOOKUP($A10,字段列表!$A:$G,6,0) -> Y | G10: =VLOOKUP($A10,字段列表!$A:$G,7,0) -> TXT-2 | H10: N
A11: 产品类别 | B11: =VLOOKUP(A11,字段列表!$A:$G,2,0) -> productCategory | C11: 通过"工单号"获取 | D11: =VLOOKUP($A11,字段列表!$A:$G,3,0) -> VARCHAR | E11: =VLOOKUP($A11,字段列表!$A:$G,5,0) -> - | F11: =VLOOKUP($A11,字段列表!$A:$G,6,0) -> Y | G11: =VLOOKUP($A11,字段列表!$A:$G,7,0) -> SEL-2 | H11: N
A12: 容量 | B12: =VLOOKUP(A12,字段列表!$A:$G,2,0) -> capacity | C12: 通过"工单号"获取 | D12: =VLOOKUP($A12,字段列表!$A:$G,3,0) -> VARCHAR | E12: =VLOOKUP($A12,字段列表!$A:$G,5,0) -> - | F12: =VLOOKUP($A12,字段列表!$A:$G,6,0) -> Y | G12: =VLOOKUP($A12,字段列表!$A:$G,7,0) -> SEL-2 | H12: N
A13: 产品PN | B13: =VLOOKUP(A13,字段列表!$A:$G,2,0) -> productPn | C13: 通过"工单号"获取 | D13: =VLOOKUP($A13,字段列表!$A:$G,3,0) -> VARCHAR | E13: =VLOOKUP($A13,字段列表!$A:$G,5,0) -> - | F13: =VLOOKUP($A13,字段列表!$A:$G,6,0) -> Y | G13: =VLOOKUP($A13,字段列表!$A:$G,7,0) -> TXT-2 | H13: N
... A17: 工单状态 | B17: =VLOOKUP(A17,字段列表!$A:$G,2,0) -> workOrderStatus | C17: 通过"工单号"获取 | D17: =VLOOKUP($A17,字段列表!$A:$G,3,0) -> VARCHAR | E17: =VLOOKUP($A17,字段列表!$A:$G,5,0) -> - | F17: =VLOOKUP($A17,字段列表!$A:$G,6,0) -> Y | G17: =VLOOKUP($A17,字段列表!$A:$G,7,0) -> SEL-2 | H17: N
A18: 工单号 | B18: =VLOOKUP(A18,字段列表!$A:$G,2,0) -> workOrderNo | C18: 通过屏幕“M1 工单齐套明细”选择的"供给明细-WO"跳转到该屏幕 WO： 输入 行项"组件编码"&"组织" 从"工单信息表内"筛选出满足以下条件的记录 物料编码 = 输入行项目料号 且 工单状态="已发放"or"未发放" 取查询到数据的"剩余数量M_QUANTITY_REMAINING"、"起始完成日期M_SCHEDULED_COMPLETION_DATE" | D18: =VLOOKUP($A18,字段列表!$A:$G,3,0) -> VARCHAR | E18: =VLOOKUP($A18,字段列表!$A:$G,5,0) -> Y | F18: =VLOOKUP($A18,字段列表!$A:$G,6,0) -> Y | G18: =VLOOKUP($A18,字段列表!$A:$G,7,0) -> TXT-1 | H18: N | I18: 通过在M1/M3屏幕，点击"供给明细-WO"以右侧抽屉的方式弹窗
A19: 工单优先级 | B19: =VLOOKUP(A19,字段列表!$A:$G,2,0) -> workOrderPriority | C19: 在"工单优先级维护"表内通过"工单号"获取 | D19: =VLOOKUP($A19,字段列表!$A:$G,3,0) -> INT | E19: =VLOOKUP($A19,字段列表!$A:$G,5,0) -> Y | F19: =VLOOKUP($A19,字段列表!$A:$G,6,0) -> Y | G19: =VLOOKUP($A19,字段列表!$A:$G,7,0) -> NUM | H19: N
A20: 转单人 | B20: =VLOOKUP(A20,字段列表!$A:$G,2,0) -> transferBy | C20: 通过"工单号"获取 | D20: =VLOOKUP($A20,字段列表!$A:$G,3,0) -> VARCHAR | E20: =VLOOKUP($A20,字段列表!$A:$G,5,0) -> - | F20: =VLOOKUP($A20,字段列表!$A:$G,6,0) -> Y | G20: =VLOOKUP($A20,字段列表!$A:$G,7,0) -> TXT-2 | H20: N
A21: 转单时间 | B21: =VLOOKUP(A21,字段列表!$A:$G,2,0) -> transferTime | C21: 通过"工单号"获取 | D21: =VLOOKUP($A21,字段列表!$A:$G,3,0) -> Date | E21: =VLOOKUP($A21,字段列表!$A:$G,5,0) -> - | F21: =VLOOKUP($A21,字段列表!$A:$G,6,0) -> Y | G21: =VLOOKUP($A21,字段列表!$A:$G,7,0) -> DATA | H21: N
A22: 转单数量 | B22: =VLOOKUP(A22,字段列表!$A:$G,2,0) -> transferQty | C22: 通过"工单号"获取 | D22: =VLOOKUP($A22,字段列表!$A:$G,3,0) -> VARCHAR | E22: =VLOOKUP($A22,字段列表!$A:$G,5,0) -> - | F22: =VLOOKUP($A22,字段列表!$A:$G,6,0) -> Y | G22: =VLOOKUP($A22,字段列表!$A:$G,7,0) -> NUM | H22: N
A23: 已完工数量 | B23: =VLOOKUP(A23,字段列表!$A:$G,2,0) -> completedQty | C23: 通过"工单号"获取 | D23: =VLOOKUP($A23,字段列表!$A:$G,3,0) -> VARCHAR | E23: =VLOOKUP($A23,字段列表!$A:$G,5,0) -> - | F23: =VLOOKUP($A23,字段列表!$A:$G,6,0) -> Y | G23: =VLOOKUP($A23,字段列表!$A:$G,7,0) -> NUM | H23: N
A24: 报废数量 | B24: =VLOOKUP(A24,字段列表!$A:$G,2,0) -> scrapQty | C24: 通过"工单号"获取 | D24: =VLOOKUP($A24,字段列表!$A:$G,3,0) -> VARCHAR | E24: =VLOOKUP($A24,字段列表!$A:$G,5,0) -> - | F24: =VLOOKUP($A24,字段列表!$A:$G,6,0) -> Y | G24: =VLOOKUP($A24,字段列表!$A:$G,7,0) -> NUM | H24: N
A25: 未完成数量 | B25: =VLOOKUP(A25,字段列表!$A:$G,2,0) -> incompleteQty | C25: 通过"工单号"获取 | D25: =VLOOKUP($A25,字段列表!$A:$G,3,0) -> VARCHAR | E25: =VLOOKUP($A25,字段列表!$A:$G,5,0) -> - | F25: =VLOOKUP($A25,字段列表!$A:$G,6,0) -> Y | G25: =VLOOKUP($A25,字段列表!$A:$G,7,0) -> NUM | H25: N
A26: 供应商编码 | B26: =VLOOKUP(A26,字段列表!$A:$G,2,0) -> supplierCode | C26: 通过"工单号"获取 | D26: =VLOOKUP($A26,字段列表!$A:$G,3,0) -> VARCHAR | E26: =VLOOKUP($A26,字段列表!$A:$G,5,0) -> - | F26: =VLOOKUP($A26,字段列表!$A:$G,6,0) -> Y | G26: =VLOOKUP($A26,字段列表!$A:$G,7,0) -> SEL-2 | H26: N
A27: 供应商简称 | B27: =VLOOKUP(A27,字段列表!$A:$G,2,0) -> supplierDesc | C27: 通过"工单号"获取 | D27: =VLOOKUP($A27,字段列表!$A:$G,3,0) -> VARCHAR | E27: =VLOOKUP($A27,字段列表!$A:$G,5,0) -> - | F27: =VLOOKUP($A27,字段列表!$A:$G,6,0) -> - | G27: =VLOOKUP($A27,字段列表!$A:$G,7,0) -> - | H27: N
A28: 要求齐料日期（起始(MRP)日期） | B28: =VLOOKUP(A28,字段列表!$A:$G,2,0) -> requiredMaterialDate | C28: 获取 工单号-起始(MRP)日期M_SCHEDULED_START_DATE | D28: =VLOOKUP($A28,字段列表!$A:$G,3,0) -> Date | E28: =VLOOKUP($A28,字段列表!$A:$G,5,0) -> - | F28: =VLOOKUP($A28,字段列表!$A:$G,6,0) -> Y | G28: =VLOOKUP($A28,字段列表!$A:$G,7,0) -> DATA | H28: N

Sheet M2 工单齐套-工单详情
A1: 字段描述 | B1: 字段名 | C1: 字段逻辑 | D1: 字符类型 | E1: 基础查询 | F1: 高级查询 | G1: 查询方式 | H1: 备注
A2: 序号 | B2: =VLOOKUP(A2,字段列表!$A:$G,2,0) -> seqNo | C2: 按照行项数自动赋值 | D2: =VLOOKUP($A2,字段列表!$A:$G,3,0) -> VARCHAR | E2: =VLOOKUP($A2,字段列表!$A:$G,5,0) -> - | F2: =VLOOKUP($A2,字段列表!$A:$G,6,0) -> - | G2: =VLOOKUP($A2,字段列表!$A:$G,7,0) -> -
A3: 配置编码 | B3: =VLOOKUP(A3,字段列表!$A:$G,2,0) -> configCode | C3: 运行时根据选择的配置编码，赋值 | D3: =VLOOKUP($A3,字段列表!$A:$G,3,0) -> VARCHAR | E3: =VLOOKUP($A3,字段列表!$A:$G,5,0) -> Y | F3: =VLOOKUP($A3,字段列表!$A:$G,6,0) -> Y | G3: =VLOOKUP($A3,字段列表!$A:$G,7,0) -> TXT-1 | H3: 查询条件必填
A4: 运行时间 | B4: =VLOOKUP(A4,字段列表!$A:$G,2,0) -> runTime | C4: 取"配置编码"运行齐套的时间赋值 | D4: =VLOOKUP($A4,字段列表!$A:$G,3,0) -> Date | E4: =VLOOKUP($A4,字段列表!$A:$G,5,0) -> - | F4: =VLOOKUP($A4,字段列表!$A:$G,6,0) -> Y | G4: =VLOOKUP($A4,字段列表!$A:$G,7,0) -> DATA
A5: 最后运行人 | B5: =VLOOKUP(A5,字段列表!$A:$G,2,0) -> lastRunBy | C5: 通过"配置编码"赋值 | D5: =VLOOKUP($A5,字段列表!$A:$G,3,0) -> VARCHAR | E5: =VLOOKUP($A5,字段列表!$A:$G,5,0) -> - | F5: =VLOOKUP($A5,字段列表!$A:$G,6,0) -> Y | G5: =VLOOKUP($A5,字段列表!$A:$G,7,0) -> TXT-2
A6: 组织 | B6: =VLOOKUP(A6,字段列表!$A:$G,2,0) -> orgName | C6: 通过"工单号"获取 | D6: =VLOOKUP($A6,字段列表!$A:$G,3,0) -> VARCHAR | E6: =VLOOKUP($A6,字段列表!$A:$G,5,0) -> Y | F6: =VLOOKUP($A6,字段列表!$A:$G,6,0) -> Y | G6: =VLOOKUP($A6,字段列表!$A:$G,7,0) -> SEL-1
A7: 订单编号 | B7: =VLOOKUP(A7,字段列表!$A:$G,2,0) -> orderNo | C7: 通过"工单号"获取，取OMS的工单头表，通过工单号，关联订单号 | D7: =VLOOKUP($A7,字段列表!$A:$G,3,0) -> VARCHAR | E7: =VLOOKUP($A7,字段列表!$A:$G,5,0) -> Y | F7: =VLOOKUP($A7,字段列表!$A:$G,6,0) -> Y | G7: =VLOOKUP($A7,字段列表!$A:$G,7,0) -> TXT-1
A8: 订单创建日期 | B8: =VLOOKUP(A8,字段列表!$A:$G,2,0) -> orderCreateDate | C8: 通过"订单编号"获取 | D8: =VLOOKUP($A8,字段列表!$A:$G,3,0) -> Date | E8: =VLOOKUP($A8,字段列表!$A:$G,5,0) -> - | F8: =VLOOKUP($A8,字段列表!$A:$G,6,0) -> Y | G8: =VLOOKUP($A8,字段列表!$A:$G,7,0) -> DATA
A9: 订单创建人 | B9: =VLOOKUP(A9,字段列表!$A:$G,2,0) -> orderCreator | C9: 通过"订单编号"获取 | D9: =VLOOKUP($A9,字段列表!$A:$G,3,0) -> VARCHAR | E9: =VLOOKUP($A9,字段列表!$A:$G,5,0) -> - | F9: =VLOOKUP($A9,字段列表!$A:$G,6,0) -> Y | G9: =VLOOKUP($A9,字段列表!$A:$G,7,0) -> TXT-2
A10: 订单类型 | B10: =VLOOKUP(A10,字段列表!$A:$G,2,0) -> orderType | C10: 通过"订单编号"获取 | D10: =VLOOKUP($A10,字段列表!$A:$G,3,0) -> VARCHAR | E10: =VLOOKUP($A10,字段列表!$A:$G,5,0) -> Y | F10: =VLOOKUP($A10,字段列表!$A:$G,6,0) -> Y | G10: =VLOOKUP($A10,字段列表!$A:$G,7,0) -> SEL-2
A11: 产品线 | B11: =VLOOKUP(A11,字段列表!$A:$G,2,0) -> productLine | C11: 通过"订单编号"获取 | D11: =VLOOKUP($A11,字段列表!$A:$G,3,0) -> VARCHAR | E11: =VLOOKUP($A11,字段列表!$A:$G,5,0) -> - | F11: =VLOOKUP($A11,字段列表!$A:$G,6,0) -> Y | G11: =VLOOKUP($A11,字段列表!$A:$G,7,0) -> SEL-2
A12: 料号 | B12: =VLOOKUP(A12,字段列表!$A:$G,2,0) -> materialCode | C12: 通过"工单号"获取 | D12: =VLOOKUP($A12,字段列表!$A:$G,3,0) -> VARCHAR | E12: =VLOOKUP($A12,字段列表!$A:$G,5,0) -> Y | F12: =VLOOKUP($A12,字段列表!$A:$G,6,0) -> Y | G12: =VLOOKUP($A12,字段列表!$A:$G,7,0) -> TXT-1
A13: 叠die数 | B13: =VLOOKUP(A13,字段列表!$A:$G,2,0) -> dieStackQty | C13: 通过"工单号-料号"获取 | D13: =VLOOKUP($A13,字段列表!$A:$G,3,0) -> VARCHAR | E13: =VLOOKUP($A13,字段列表!$A:$G,5,0) -> - | F13: =VLOOKUP($A13,字段列表!$A:$G,6,0) -> Y | G13: =VLOOKUP($A13,字段列表!$A:$G,7,0) -> TXT-2
A14: 产品类别 | B14: =VLOOKUP(A14,字段列表!$A:$G,2,0) -> productCategory | C14: 通过"工单号"获取 | D14: =VLOOKUP($A14,字段列表!$A:$G,3,0) -> VARCHAR | E14: =VLOOKUP($A14,字段列表!$A:$G,5,0) -> - | F14: =VLOOKUP($A14,字段列表!$A:$G,6,0) -> Y | G14: =VLOOKUP($A14,字段列表!$A:$G,7,0) -> SEL-2
A15: 容量 | B15: =VLOOKUP(A15,字段列表!$A:$G,2,0) -> capacity | C15: 通过"工单号"获取 | D15: =VLOOKUP($A15,字段列表!$A:$G,3,0) -> VARCHAR | E15: =VLOOKUP($A15,字段列表!$A:$G,5,0) -> - | F15: =VLOOKUP($A15,字段列表!$A:$G,6,0) -> Y | G15: =VLOOKUP($A15,字段列表!$A:$G,7,0) -> SEL-2
... A37: 剩余齐套数 | B37: =VLOOKUP(A37,字段列表!$A:$G,2,0) -> remainingKitQty | C37: 查"工单齐套明细表"，通过"工单号" ，遍历"未齐套数"，取最小值，赋值 | D37: =VLOOKUP($A37,字段列表!$A:$G,3,0) -> VARCHAR | E37: =VLOOKUP($A37,字段列表!$A:$G,5,0) -> - | F37: =VLOOKUP($A37,字段列表!$A:$G,6,0) -> Y | G37: =VLOOKUP($A37,字段列表!$A:$G,7,0) -> NUM
A38: 工单当前齐套数 | B38: =VLOOKUP(A38,字段列表!$A:$G,2,0) -> committedSumQty | C38: 查"工单齐套明细表"，通过"工单号" ，遍历"工单当前齐套数"，取最小值，赋值 | D38: =VLOOKUP($A38,字段列表!$A:$G,3,0) -> VARCHAR | E38: =VLOOKUP($A38,字段列表!$A:$G,5,0) -> - | F38: =VLOOKUP($A38,字段列表!$A:$G,6,0) -> Y | G38: =VLOOKUP($A38,字段列表!$A:$G,7,0) -> NUM | J38: ·
A39: 齐套进度 | B39: =VLOOKUP(A39,字段列表!$A:$G,2,0) -> kitProgress | C39: 遍历"工单齐套明细"表，select "组件编码" 行数，计分母。 Select "工单缺料数量" 计，IF "工单缺料数量" ＜0 ，行数。计分子。 该字段提供接口，点击后，页面右侧弹出窗口"M2_1 工单齐套-工单详细-工单组件信息"页面 | D39: =VLOOKUP($A39,字段列表!$A:$G,3,0) -> VARCHAR | E39: =VLOOKUP($A39,字段列表!$A:$G,5,0) -> - | F39: =VLOOKUP($A39,字段列表!$A:$G,6,0) -> - | G39: =VLOOKUP($A39,字段列表!$A:$G,7,0) -> NUM | H39: 该字段提供接口，点击后，页面右侧弹出窗口"M2_1 工单齐套-工单详细-工单组件信息"页面

Sheet M2_1 工单齐套-工单详细-工单组件信息
A1: 屏幕结构 | B1: 字段描述 | C1: 字段名 | D1: 字段逻辑 | E1: 字符类型 | F1: 基础查询 | G1: 高级查询 | H1: 查询方式 | I1: 备注
A2: head | B2: 配置编码 | C2: =VLOOKUP(B2,字段列表!$A:$G,2,0) -> configCode | D2: 根据所选行的"工单号"带出 | E2: =VLOOKUP($B2,字段列表!$A:$G,3,0) -> VARCHAR | F2: N/A | G2: N/A | H2: N/A
B3: 组织 | C3: =VLOOKUP(B3,字段列表!$A:$G,2,0) -> orgName | D3: 根据所选行的"工单号"带出 | E3: =VLOOKUP($B3,字段列表!$A:$G,3,0) -> VARCHAR | F3: N/A | G3: N/A | H3: N/A
B4: 料号 | C4: =VLOOKUP(B4,字段列表!$A:$G,2,0) -> materialCode | D4: 根据所选行的"工单号"带出 | E4: =VLOOKUP($B4,字段列表!$A:$G,3,0) -> VARCHAR | F4: N/A | G4: N/A | H4: N/A
B5: 下单数量 | C5: =VLOOKUP(B5,字段列表!$A:$G,2,0) -> orderQty | D5: 根据所选行的"工单号"带出 | E5: =VLOOKUP($B5,字段列表!$A:$G,3,0) -> VARCHAR | F5: N/A | G5: N/A | H5: N/A
B6: 要求完成日期 | C6: =VLOOKUP(B6,字段列表!$A:$G,2,0) -> requiredCompletionDate | D6: 根据所选行的"工单号"带出 | E6: =VLOOKUP($B6,字段列表!$A:$G,3,0) -> Date | F6: N/A | G6: N/A | H6: N/A
B7: 工单号 | C7: =VLOOKUP(B7,字段列表!$A:$G,2,0) -> workOrderNo | D7: 通过在屏幕M2 工单齐套-工单详情，点击物料编码，跳转到该屏幕，根据所选行的"工单号"带出 | E7: =VLOOKUP($B7,字段列表!$A:$G,3,0) -> VARCHAR | F7: N/A | G7: N/A | H7: N/A
B8: 工单优先级 | C8: =VLOOKUP(B8,字段列表!$A:$G,2,0) -> workOrderPriority | D8: 根据所选行的"工单号"带出 | E8: =VLOOKUP($B8,字段列表!$A:$G,3,0) -> INT | F8: N/A | G8: N/A | H8: N/A
B9: 转单人 | C9: =VLOOKUP(B9,字段列表!$A:$G,2,0) -> transferBy | D9: 根据所选行的"工单号"带出 | E9: =VLOOKUP($B9,字段列表!$A:$G,3,0) -> VARCHAR | F9: N/A | G9: N/A | H9: N/A
B10: 是否齐套 | C10: =VLOOKUP(B10,字段列表!$A:$G,2,0) -> isKitComplete | D10: 针对工单关联的组件齐套情况判断，工单关联组件，任意一料号不齐套，该工单为不齐套，反之齐套 | E10: =VLOOKUP($B10,字段列表!$A:$G,3,0) -> Boolean | F10: N/A | G10: N/A | H10: N/A | I10: 针对工单判断
A11: ITEM | B11: 组件物料 | C11: =VLOOKUP(B11,字段列表!$A:$G,2,0) -> componentMaterialCode | D11: 根据所选行的"工单号"带出，select "M1 工单齐套明细"数据，增加点击页面跳转，点击后可跳转到"M3 工单齐套-物料详情"屏幕，按照点击料号默认筛选 | E11: =VLOOKUP($B11,字段列表!$A:$G,3,0) -> VARCHAR | F11: N/A | G11: N/A | H11: N/A | I11: 点击页面跳转，点击后可跳转到"M3 工单齐套-物料详情"屏幕，按照点击料号默认筛选
B12: 组件物料描述 | C12: =VLOOKUP(B12,字段列表!$A:$G,2,0) -> componentMaterialDesc | D12: 根据所选行的"工单号"带出，select "M1 工单齐套明细"数据 | E12: =VLOOKUP($B12,字段列表!$A:$G,3,0) -> VARCHAR | F12: N/A | G12: N/A | H12: N/A
B13: 组件责任方 | C13: =VLOOKUP(B13,字段列表!$A:$G,2,0) -> componentResponsibleParty | D13: 根据所选行的"工单号"带出，select "M1 工单齐套明细"数据 | E13: =VLOOKUP($B13,字段列表!$A:$G,3,0) -> VARCHAR | F13: N/A | G13: N/A | H13: N/A
B14: 是否资源 | C14: =VLOOKUP(B14,字段列表!$A:$G,2,0) -> isResource | D14: 根据所选行的"工单号"带出，select "M1 工单齐套明细"数据 | E14: =VLOOKUP($B14,字段列表!$A:$G,3,0) -> Boolean | F14: N/A | G14: N/A | H14: N/A
B15: 单位用量 | C15: =VLOOKUP(B15,字段列表!$A:$G,2,0) -> unitUsage | D15: 根据所选行的"工单号"带出，select "M1 工单齐套明细"数据 | E15: =VLOOKUP($B15,字段列表!$A:$G,3,0) -> VARCHAR | F15: N/A | G15: N/A | H15: N/A
B16: 必需 | C16: =VLOOKUP(B16,字段列表!$A:$G,2,0) -> isRequired | D16: 根据所选行的"工单号"带出，select "M1 工单齐套明细"数据 | E16: =VLOOKUP($B16,字段列表!$A:$G,3,0) -> VARCHAR | F16: N/A | G16: N/A | H16: N/A
B17: 产出率 | C17: =VLOOKUP(B17,字段列表!$A:$G,2,0) -> yieldRate | D17: 根据所选行的"工单号"带出，select "M1 工单齐套明细"数据 | E17: =VLOOKUP($B17,字段列表!$A:$G,3,0) -> VARCHAR | F17: N/A | G17: N/A | H17: N/A
B18: 已发料量 | C18: =VLOOKUP(B18,字段列表!$A:$G,2,0) -> issuedQty | D18: 根据所选行的"工单号"带出，select "M1 工单齐套明细"数据 | E18: =VLOOKUP($B18,字段列表!$A:$G,3,0) -> VARCHAR | F18: N/A | G18: N/A | H18: N/A
B19: 未发料数量 | C19: =VLOOKUP(B19,字段列表!$A:$G,2,0) -> unIssuedQty | D19: 根据所选行的"工单号"带出，select "M1 工单齐套明细"数据 | E19: =VLOOKUP($B19,字段列表!$A:$G,3,0) -> VARCHAR | F19: N/A | G19: N/A | H19: N/A
B20: 可用量 | C20: =VLOOKUP(B20,字段列表!$A:$G,2,0) -> availableQty | D20: 根据所选行的"工单号"带出，select "M1 工单齐套明细"数据 | E20: =VLOOKUP($B20,字段列表!$A:$G,3,0) -> VARCHAR | F20: N/A | G20: N/A | H20: N/A
B21: 现存数量 | C21: =VLOOKUP(B21,字段列表!$A:$G,2,0) -> onHandQty | D21: 根据所选行的"工单号"带出，select "M1 工单齐套明细"数据 | E21: =VLOOKUP($B21,字段列表!$A:$G,3,0) -> VARCHAR | F21: N/A | G21: N/A | H21: N/A
B22: 发料仓 | C22: =VLOOKUP(B22,字段列表!$A:$G,2,0) -> issueWarehouse | D22: 根据所选行的"工单号"带出，select "M1 工单齐套明细"数据 | E22: =VLOOKUP($B22,字段列表!$A:$G,3,0) -> VARCHAR | F22: N/A | G22: N/A | H22: N/A
B23: 配置库存数量 | C23: =VLOOKUP(B23,字段列表!$A:$G,2,0) -> configInventoryQty | D23: 根据所选行的"工单号"带出，select "M1 工单齐套明细"数据 | E23: =VLOOKUP($B23,字段列表!$A:$G,3,0) -> VARCHAR | F23: N/A | G23: N/A | H23: N/A
... B34: 是否存在替代料 | C34: =VLOOKUP(B34,字段列表!$A:$G,2,0) -> hasAlternativeMaterial | D34: 根据所选行的"工单号"带出，select "M1 工单齐套明细"数据 | E34: =VLOOKUP($B34,字段列表!$A:$G,3,0) -> Boolean | F34: N/A | G34: N/A | H34: N/A
B35: 替代料及库存 | C35: =VLOOKUP(B35,字段列表!$A:$G,2,0) -> alternativeMaterialStock | D35: 根据所选行的"工单号"带出，select "M1 工单齐套明细"数据，点击页面跳转，点击后可跳转到"C1_1 替代料明细"屏幕，按照点击料号默认筛选 | E35: =VLOOKUP($B35,字段列表!$A:$G,3,0) -> _ | F35: N/A | G35: N/A | H35: N/A | I35: 点击页面跳转，点击后可跳转到"C1_1 替代料明细"屏幕，按照点击料号默认筛选
B36: 供给明细 | C36: =VLOOKUP(B36,字段列表!$A:$G,2,0) -> supplyDetails | D36: 根据所选行的"工单号"带出，select "M1 工单齐套明细"数据，与M1 工单齐套明细一样，支持跳转到供给清单 | E36: =VLOOKUP($B36,字段列表!$A:$G,3,0) -> _ | F36: N/A | G36: N/A | H36: N/A | I36: 与M1 工单齐套明细一样，支持跳转到供给清单
B37: 是否齐套 | C37: =VLOOKUP(B37,字段列表!$A:$G,2,0) -> isKitComplete | D37: IF "工单缺料数量" = 0 "齐套" ELSE "不齐套" | E37: =VLOOKUP($B37,字段列表!$A:$G,3,0) -> Boolean | F37: N/A | G37: N/A | H37: N/A | I37: 针对物料判断

Sheet M3 工单齐套-物料详细
A1: 字段描述 | B1: 字段名 | C1: 字段逻辑 | D1: 字符类型 | E1: 基础查询 | F1: 高级查询 | G1: 查询方式 | H1: 备注
A2: 序号 | B2: =VLOOKUP(A2,字段列表!$A:$G,2,0) -> seqNo | C2: 自动赋值 | D2: =VLOOKUP($A2,字段列表!$A:$G,3,0) -> VARCHAR | E2: =VLOOKUP($A2,字段列表!$A:$G,5,0) -> - | F2: =VLOOKUP($A2,字段列表!$A:$G,6,0) -> - | G2: =VLOOKUP($A2,字段列表!$A:$G,7,0) -> -
A3: 配置编码 | B3: =VLOOKUP(A3,字段列表!$A:$G,2,0) -> configCode | C3: 根据"M1 工单齐套明细"的数据 | D3: =VLOOKUP($A3,字段列表!$A:$G,3,0) -> VARCHAR | E3: =VLOOKUP($A3,字段列表!$A:$G,5,0) -> Y | F3: =VLOOKUP($A3,字段列表!$A:$G,6,0) -> Y | G3: =VLOOKUP($A3,字段列表!$A:$G,7,0) -> TXT-1 | H3: 查询条件必填
A4: 配置描述 | B4: =VLOOKUP(A4,字段列表!$A:$G,2,0) -> configDesc | C4: 通过"配置编码"取值 | D4: =VLOOKUP($A4,字段列表!$A:$G,3,0) -> VARCHAR | E4: =VLOOKUP($A4,字段列表!$A:$G,5,0) -> - | F4: =VLOOKUP($A4,字段列表!$A:$G,6,0) -> Y | G4: =VLOOKUP($A4,字段列表!$A:$G,7,0) -> TXT-2
A5: 组织 | B5: =VLOOKUP(A5,字段列表!$A:$G,2,0) -> orgName | C5: 取"M1 工单齐套明细"清单，根据"组件物料"，反找所属"工单号"的"组织"，若对应多个组织有同一料号，则按照组织分行 | D5: =VLOOKUP($A5,字段列表!$A:$G,3,0) -> VARCHAR | E5: =VLOOKUP($A5,字段列表!$A:$G,5,0) -> Y | F5: =VLOOKUP($A5,字段列表!$A:$G,6,0) -> Y | G5: =VLOOKUP($A5,字段列表!$A:$G,7,0) -> SEL-1
A6: 组件物料 | B6: =VLOOKUP(A6,字段列表!$A:$G,2,0) -> componentMaterialCode | C6: 根据"M1 工单齐套明细"清单，按"配置编码"&"组件物料"&"组织"，去重，IF"组件物料-是否资源"=Y，按照按"配置编码"&"组件物料"&"组织"&"产品线"，去重 | D6: =VLOOKUP($A6,字段列表!$A:$G,3,0) -> VARCHAR | E6: =VLOOKUP($A6,字段列表!$A:$G,5,0) -> Y | F6: =VLOOKUP($A6,字段列表!$A:$G,6,0) -> Y | G6: =VLOOKUP($A6,字段列表!$A:$G,7,0) -> TXT-1
A7: 组件物料描述 | B7: =VLOOKUP(A7,字段列表!$A:$G,2,0) -> componentMaterialDesc | C7: "组件物料"获取"组件物料描述" | D7: =VLOOKUP($A7,字段列表!$A:$G,3,0) -> VARCHAR | E7: =VLOOKUP($A7,字段列表!$A:$G,5,0) -> - | F7: =VLOOKUP($A7,字段列表!$A:$G,6,0) -> Y | G7: =VLOOKUP($A7,字段列表!$A:$G,7,0) -> TXT-2
A8: LT | B8: =VLOOKUP(A8,字段列表!$A:$G,2,0) -> componentLeadTime | C8: 根据"M1 工单齐套明细"清单，按"配置编码"&"组件物料"&"组织"&"产品线"，获取EBS"固定供应天数 FIXED_DAYS_SUPPLY_MIR' | D8: =VLOOKUP($A8,字段列表!$A:$G,3,0) -> VARCHAR | E8: =VLOOKUP($A8,字段列表!$A:$G,5,0) -> - | F8: =VLOOKUP($A8,字段列表!$A:$G,6,0) -> Y | G8: =VLOOKUP($A8,字段列表!$A:$G,7,0) -> NUM
A9: 零部件类别 | B9: =VLOOKUP(A9,字段列表!$A:$G,2,0) -> componentCategory | C9: 根据"M1 工单齐套明细"清单，按"配置编码"&"组件物料"&"组织"，通过组件料号，取EBS“NCITEM_EXTEND_V-ITEM_WLLB” | D9: =VLOOKUP($A9,字段列表!$A:$G,3,0) -> VARCHAR | E9: =VLOOKUP($A9,字段列表!$A:$G,5,0) -> - | F9: =VLOOKUP($A9,字段列表!$A:$G,6,0) -> Y | G9: =VLOOKUP($A9,字段列表!$A:$G,7,0) -> SEL-2
A10: 组件分类 | B10: =VLOOKUP(A10,字段列表!$A:$G,2,0) -> componentType | C10: 配置表"C3 组件责任方配置"，通过"零部件类别"，取对应"组件分类" | D10: =VLOOKUP($A10,字段列表!$A:$G,3,0) -> VARCHAR | E10: =VLOOKUP($A10,字段列表!$A:$G,5,0) -> - | F10: =VLOOKUP($A10,字段列表!$A:$G,6,0) -> Y | G10: =VLOOKUP($A10,字段列表!$A:$G,7,0) -> SEL-2
A11: 组件责任方 | B11: =VLOOKUP(A11,字段列表!$A:$G,2,0) -> componentResponsibleParty | C11: 配置表"C3 组件责任方配置"，通过"零部件类别"，取对应"组件分类-组件责任方" | D11: =VLOOKUP($A11,字段列表!$A:$G,3,0) -> VARCHAR | E11: =VLOOKUP($A11,字段列表!$A:$G,5,0) -> Y | F11: =VLOOKUP($A11,字段列表!$A:$G,6,0) -> Y | G11: =VLOOKUP($A11,字段列表!$A:$G,7,0) -> TXT-2
A12: 产品线 | B12: =VLOOKUP(A12,字段列表!$A:$G,2,0) -> productLine | C12: 按"配置编码"&"组件物料"&"组织"，IF"组件物料-是否资源"=Y，按"产品线"分行 | D12: =VLOOKUP($A12,字段列表!$A:$G,3,0) -> VARCHAR | E12: =VLOOKUP($A12,字段列表!$A:$G,5,0) -> - | F12: =VLOOKUP($A12,字段列表!$A:$G,6,0) -> Y | G12: =VLOOKUP($A12,字段列表!$A:$G,7,0) -> SEL-2
A13: 是否资源 | B13: =VLOOKUP(A13,字段列表!$A:$G,2,0) -> isResource | C13: 根据组件编码，取EBS物料主数据，字段"IS_RESOURCES_FLAG" Y为产品管控物料，N为非产品线管控物料 | D13: =VLOOKUP($A13,字段列表!$A:$G,3,0) -> Boolean | E13: =VLOOKUP($A13,字段列表!$A:$G,5,0) -> - | F13: =VLOOKUP($A13,字段列表!$A:$G,6,0) -> Y | G13: =VLOOKUP($A13,字段列表!$A:$G,7,0) -> SEL-1 | H13: Y/N
A14: 理论可用库存 | B14: =VLOOKUP(A14,字段列表!$A:$G,2,0) -> theoreticalAvailableStock | C14: 按"配置编码"&"组件物料"&"组织"&"产品线"，到表"M1 工单齐套明细"取"理论可用库存"，最小值，IF"组件物料-是否资源"=Y，按照按"配置编码"&"组件物料"&"组织"&"产品线"，去重 | D14: =VLOOKUP($A14,字段列表!$A:$G,3,0) -> VARCHAR | E14: =VLOOKUP($A14,字段列表!$A:$G,5,0) -> - | F14: =VLOOKUP($A14,字段列表!$A:$G,6,0) -> Y | G14: =VLOOKUP($A14,字段列表!$A:$G,7,0) -> NUM
A15: 理论可用库存(含PO&工单) | B15: =VLOOKUP(A15,字段列表!$A:$G,2,0) -> theoreticalAvailableStockInclPoWo | C15: 按"配置编码"&"组件物料"&"组织"&"产品线"，到表"M1 工单齐套明细"取"理论可用库存(含PO&工单)" | D15: =VLOOKUP($A15,字段列表!$A:$G,3,0) -> VARCHAR | E15: =VLOOKUP($A15,字段列表!$A:$G,5,0) -> - | F15: =VLOOKUP($A15,字段列表!$A:$G,6,0) -> Y | G15: =VLOOKUP($A15,字段列表!$A:$G,7,0) -> NUM
A16: 可用库存缺料数 | B16: =VLOOKUP(A16,字段列表!$A:$G,2,0) -> availableStockShortageQty | C16: 按"配置编码"&"组件物料"&"组织"&"产品线"，到表"M1 工单齐套明细"取"理论可用库存(含PO&工单)"，取最小值 | D16: =VLOOKUP($A16,字段列表!$A:$G,3,0) -> VARCHAR | E16: =VLOOKUP($A16,字段列表!$A:$G,5,0) -> - | F16: =VLOOKUP($A16,字段列表!$A:$G,6,0) -> Y | G16: =VLOOKUP($A16,字段列表!$A:$G,7,0) -> NUM
A17: 未发料数量 | B17: =VLOOKUP(A17,字段列表!$A:$G,2,0) -> unIssuedQty | C17: 按"配置编码"&"组件物料"&"组织"&"产品线"，取汇总对应的"未发料数量"赋值到该栏位，IF"组件物料-是否资源"=Y，按照按"配置编码"&"组件物料"&"组织"&"产品线" | D17: =VLOOKUP($A17,字段列表!$A:$G,3,0) -> VARCHAR | E17: =VLOOKUP($A17,字段列表!$A:$G,5,0) -> - | F17: =VLOOKUP($A17,字段列表!$A:$G,6,0) -> Y | G17: =VLOOKUP($A17,字段列表!$A:$G,7,0) -> NUM
A18: 已承诺数量 | B18: =VLOOKUP(A18,字段列表!$A:$G,2,0) -> CommittedQty | C18: 按"配置编码"&"组件物料"&"组织"&"产品线"，select "M1 工单齐套明细"，取满足以下条件的数据进行汇总，赋值到该栏位 工单缺料数量 不会大于0,"未发料数量"不会为负数。 IF "工单缺料数量"= 0 AND "未发料数量" != 0 (齐套运算时，所在行的组件，配置库存可以满足，工单缺料数量=0，并且未发料数量不等于0，代表工单没有进行投料完成，可以进行库存承诺，此时该行的承诺数量就会等于未发料数量) sum "未发料数量" ELSE IF "工单缺料数量"＜0，AND 丨"工单缺料数量"丨(绝对值) != "未发料数量"(工单缺料数量小于零，且绝对值状态下不等于未发料数量，相当于该行，当前有部分库存满足了该行，) = "工单缺料数量"+"未发料数量"， ELSE IF "工单缺料数量" ＜0，不考虑相关行，其他满足条件的数据按照以上条件汇总计算后，赋值到该栏位 | D18: =VLOOKUP($A18,字段列表!$A:$G,3,0) -> VARCHAR | E18: =VLOOKUP($A18,字段列表!$A:$G,5,0) -> - | F18: =VLOOKUP($A18,字段列表!$A:$G,6,0) -> Y | G18: =VLOOKUP($A18,字段列表!$A:$G,7,0) -> NUM
A19: 现存数量 | B19: =VLOOKUP(A19,字段列表!$A:$G,2,0) -> onHandQty | C19: 根据"M1 工单齐套明细"清单，按"配置编码"&"组件物料"&"组织"，通过组件料号，取EBS 的"现存数量"LIMIT_ONHAND_QUANTITY字段 | D19: =VLOOKUP($A19,字段列表!$A:$G,3,0) -> VARCHAR | E19: =VLOOKUP($A19,字段列表!$A:$G,5,0) -> - | F19: =VLOOKUP($A19,字段列表!$A:$G,6,0) -> Y | G19: =VLOOKUP($A19,字段列表!$A:$G,7,0) -> NUM
A20: 配置库存数量 | B20: =VLOOKUP(A20,字段列表!$A:$G,2,0) -> configInventoryQty | C20: 按"配置编码"&"组件物料"&"组织"，取"C1 工单齐套明细" 的"配置库存数量"，IF"组件物料-是否资源"=Y，按照按"配置编码"&"组件物料"&"组织"&"产品线"取值 | D20: =VLOOKUP($A20,字段列表!$A:$G,3,0) -> VARCHAR | E20: =VLOOKUP($A20,字段列表!$A:$G,5,0) -> - | F20: =VLOOKUP($A20,字段列表!$A:$G,6,0) -> Y | G20: =VLOOKUP($A20,字段列表!$A:$G,7,0) -> NUM
A21: 现存数量 | B21: =VLOOKUP(A21,字段列表!$A:$G,2,0) -> onHandQty | C21: 按"配置编码"&"组件物料"&"组织"，取"C1 工单齐套明细" 的"现存数量"，IF"组件物料-是否资源"=Y，按照按"配置编码"&"组件物料"&"组织"&"产品线"取值 | D21: =VLOOKUP($A21,字段列表!$A:$G,3,0) -> VARCHAR | E21: =VLOOKUP($A21,字段列表!$A:$G,5,0) -> - | F21: =VLOOKUP($A21,字段列表!$A:$G,6,0) -> Y | G21: =VLOOKUP($A21,字段列表!$A:$G,7,0) -> NUM
A22: 关联工单 | B22: =VLOOKUP(A22,字段列表!$A:$G,2,0) -> #N/A | C22: 点击该字段，按照所选行的"组件编码"&"组织"反查，M1 工单齐套明细，跳转到"M3_1 工单齐套-物料详情-物料关联工单信息"，默认显示该物料关联的工单个数 | D22: =VLOOKUP($A22,字段列表!$A:$G,3,0) -> #N/A | E22: =VLOOKUP($A22,字段列表!$A:$G,5,0) -> #N/A | F22: =VLOOKUP($A22,字段列表!$A:$G,6,0) -> #N/A | G22: =VLOOKUP($A22,字段列表!$A:$G,7,0) -> #N/A | H22: 点击抽屉弹窗，M3_1屏幕
A23: 供给明细 | B23: =VLOOKUP(A23,字段列表!$A:$G,2,0) -> supplyDetails | C23: 参考M1 工单齐套明细，"供给明细字段"，提供3个链接，点击后转到，PR/PO/WO，信息表内 根据当前行"组件编码"，找如下数据： PO，跳转到T1屏幕 输入 行项"组件编码"&"组织" 从"SRM采购订单交期报表create table srm_po_allocation_lines" 筛选出满足以下条件的记录 物料编码 = 输入行项目料号 且 采购订单状态 = 打开 取查询到数据的"承诺数量"、"promise_date承诺日期" WO，跳转到M1_1屏幕，以抽屉方式弹出 输入 行项"组件编码"&"组织" 从"工单信息表内"筛选出满足以下条件的记录 物料编码 = 输入行项目料号 且 工单状态="已发放"or"未发放" 取查询到数据的"剩余数量M_QUANTITY_REMAINING"、"起始完成日期M_SCHEDULED_COMPLETION_DATE" PR，跳转到T2屏幕 输入 行项"组件编码"&"组织" 从"PR信息表" 筛选出满足以下条件的记录 物料编码 = 输入行项目料号 且 PR状态 = 打开 取查询到数据的"下单数量"、"交货日期" | D23: =VLOOKUP($A23,字段列表!$A:$G,3,0) -> _ | E23: =VLOOKUP($A23,字段列表!$A:$G,5,0) -> - | F23: =VLOOKUP($A23,字段列表!$A:$G,6,0) -> - | G23: =VLOOKUP($A23,字段列表!$A:$G,7,0) -> - | H23: 固定右侧

Sheet M3_1工单齐套-物料详情-物料关联工单信息
A1: 屏幕结构 | B1: 字段描述 | C1: 字段名 | D1: 字段逻辑 | E1: 字符类型 | F1: 基础查询 | G1: 高级查询 | H1: 查询方式 | I1: 备注
A2: head | B2: 配置编码 | C2: =VLOOKUP(B2,字段列表!$A:$G,2,0) -> configCode | D2: 通过点击屏幕"M3 工单齐套 物料详情"，所选"组件编码"带出该字段 | E2: =VLOOKUP($B2,字段列表!$A:$G,3,0) -> VARCHAR | F2: N/A | G2: N/A | H2: N/A
B3: 组织 | D3: 通过点击屏幕"M3 工单齐套 物料详情"，所选"组件编码"带出该字段 | E3: =VLOOKUP($B3,字段列表!$A:$G,3,0) -> VARCHAR | F3: N/A | G3: N/A | H3: N/A
B4: 组件物料 | C4: =VLOOKUP(B4,字段列表!$A:$G,2,0) -> componentMaterialCode | D4: 通过点击屏幕"M3 工单齐套 物料详情"抽屉弹窗，出该屏幕，根据所选组件料号呈现数据 | E4: =VLOOKUP($B4,字段列表!$A:$G,3,0) -> VARCHAR | F4: N/A | G4: N/A | H4: N/A | I4: 通过点击屏幕"M3 工单齐套 物料详情"抽屉弹窗，出该屏幕，根据所选组件料号呈现数据
B5: 组件物料描述 | C5: =VLOOKUP(B5,字段列表!$A:$G,2,0) -> componentMaterialDesc | D5: 通过点击屏幕"M3 工单齐套 物料详情"，所选"组件编码"带出该字段 | E5: =VLOOKUP($B5,字段列表!$A:$G,3,0) -> VARCHAR | F5: N/A | G5: N/A | H5: N/A
B6: 配置库存数量 | C6: =VLOOKUP(B6,字段列表!$A:$G,2,0) -> configInventoryQty | D6: 通过点击屏幕"M3 工单齐套 物料详情"，所选"组件编码"带出该字段 | E6: =VLOOKUP($B6,字段列表!$A:$G,3,0) -> VARCHAR | F6: N/A | G6: N/A | H6: N/A
